2020-11-19 13:23:16,077 (2146/MainThread) litecli.main ERROR - sql: '.explain', error: OperationalError('near ".": syntax error')
2020-11-19 13:23:16,082 (2146/MainThread) litecli.main ERROR - traceback: 'Traceback (most recent call last):\n  File "/usr/local/lib/python3.8/site-packages/litecli/sqlexecute.py", line 121, in run\n    for result in special.execute(cur, sql):\n  File "/usr/local/lib/python3.8/site-packages/litecli/packages/special/main.py", line 109, in execute\n    raise CommandNotFound\nlitecli.packages.special.main.CommandNotFound\n\nDuring handling of the above exception, another exception occurred:\n\nTraceback (most recent call last):\n  File "/usr/local/lib/python3.8/site-packages/litecli/main.py", line 441, in one_iteration\n    for title, cur, headers, status in res:\n  File "/usr/local/lib/python3.8/site-packages/litecli/sqlexecute.py", line 125, in run\n    cur.execute(sql)\nsqlite3.OperationalError: near ".": syntax error\n'
2020-11-19 13:23:29,892 (2146/MainThread) litecli.main ERROR - sql: '.explain', error: OperationalError('near ".": syntax error')
2020-11-19 13:23:29,893 (2146/MainThread) litecli.main ERROR - traceback: 'Traceback (most recent call last):\n  File "/usr/local/lib/python3.8/site-packages/litecli/sqlexecute.py", line 121, in run\n    for result in special.execute(cur, sql):\n  File "/usr/local/lib/python3.8/site-packages/litecli/packages/special/main.py", line 109, in execute\n    raise CommandNotFound\nlitecli.packages.special.main.CommandNotFound\n\nDuring handling of the above exception, another exception occurred:\n\nTraceback (most recent call last):\n  File "/usr/local/lib/python3.8/site-packages/litecli/main.py", line 441, in one_iteration\n    for title, cur, headers, status in res:\n  File "/usr/local/lib/python3.8/site-packages/litecli/sqlexecute.py", line 125, in run\n    cur.execute(sql)\nsqlite3.OperationalError: near ".": syntax error\n'
2020-11-19 13:23:37,207 (2146/MainThread) litecli.main ERROR - sql: 'ex', error: OperationalError('near "ex": syntax error')
2020-11-19 13:23:37,208 (2146/MainThread) litecli.main ERROR - traceback: 'Traceback (most recent call last):\n  File "/usr/local/lib/python3.8/site-packages/litecli/sqlexecute.py", line 121, in run\n    for result in special.execute(cur, sql):\n  File "/usr/local/lib/python3.8/site-packages/litecli/packages/special/main.py", line 109, in execute\n    raise CommandNotFound\nlitecli.packages.special.main.CommandNotFound\n\nDuring handling of the above exception, another exception occurred:\n\nTraceback (most recent call last):\n  File "/usr/local/lib/python3.8/site-packages/litecli/main.py", line 441, in one_iteration\n    for title, cur, headers, status in res:\n  File "/usr/local/lib/python3.8/site-packages/litecli/sqlexecute.py", line 125, in run\n    cur.execute(sql)\nsqlite3.OperationalError: near "ex": syntax error\n'
2020-11-19 13:23:41,706 (2146/MainThread) litecli.main ERROR - sql: 'explain', error: OperationalError('incomplete input')
2020-11-19 13:23:41,706 (2146/MainThread) litecli.main ERROR - traceback: 'Traceback (most recent call last):\n  File "/usr/local/lib/python3.8/site-packages/litecli/sqlexecute.py", line 121, in run\n    for result in special.execute(cur, sql):\n  File "/usr/local/lib/python3.8/site-packages/litecli/packages/special/main.py", line 109, in execute\n    raise CommandNotFound\nlitecli.packages.special.main.CommandNotFound\n\nDuring handling of the above exception, another exception occurred:\n\nTraceback (most recent call last):\n  File "/usr/local/lib/python3.8/site-packages/litecli/main.py", line 441, in one_iteration\n    for title, cur, headers, status in res:\n  File "/usr/local/lib/python3.8/site-packages/litecli/sqlexecute.py", line 125, in run\n    cur.execute(sql)\nsqlite3.OperationalError: incomplete input\n'
2020-11-19 13:23:44,442 (2146/MainThread) litecli.main ERROR - sql: 'ls', error: OperationalError('near "ls": syntax error')
2020-11-19 13:23:44,443 (2146/MainThread) litecli.main ERROR - traceback: 'Traceback (most recent call last):\n  File "/usr/local/lib/python3.8/site-packages/litecli/sqlexecute.py", line 121, in run\n    for result in special.execute(cur, sql):\n  File "/usr/local/lib/python3.8/site-packages/litecli/packages/special/main.py", line 109, in execute\n    raise CommandNotFound\nlitecli.packages.special.main.CommandNotFound\n\nDuring handling of the above exception, another exception occurred:\n\nTraceback (most recent call last):\n  File "/usr/local/lib/python3.8/site-packages/litecli/main.py", line 441, in one_iteration\n    for title, cur, headers, status in res:\n  File "/usr/local/lib/python3.8/site-packages/litecli/sqlexecute.py", line 125, in run\n    cur.execute(sql)\nsqlite3.OperationalError: near "ls": syntax error\n'
2020-11-19 13:24:20,876 (2146/MainThread) litecli.main ERROR - sql: '.ta', error: OperationalError('near ".": syntax error')
2020-11-19 13:24:20,877 (2146/MainThread) litecli.main ERROR - traceback: 'Traceback (most recent call last):\n  File "/usr/local/lib/python3.8/site-packages/litecli/sqlexecute.py", line 121, in run\n    for result in special.execute(cur, sql):\n  File "/usr/local/lib/python3.8/site-packages/litecli/packages/special/main.py", line 109, in execute\n    raise CommandNotFound\nlitecli.packages.special.main.CommandNotFound\n\nDuring handling of the above exception, another exception occurred:\n\nTraceback (most recent call last):\n  File "/usr/local/lib/python3.8/site-packages/litecli/main.py", line 441, in one_iteration\n    for title, cur, headers, status in res:\n  File "/usr/local/lib/python3.8/site-packages/litecli/sqlexecute.py", line 125, in run\n    cur.execute(sql)\nsqlite3.OperationalError: near ".": syntax error\n'
2020-11-19 13:25:21,765 (2303/MainThread) litecli.main ERROR - sql: 'ex', error: OperationalError('near "ex": syntax error')
2020-11-19 13:25:21,766 (2303/MainThread) litecli.main ERROR - traceback: 'Traceback (most recent call last):\n  File "/usr/local/lib/python3.8/site-packages/litecli/sqlexecute.py", line 121, in run\n    for result in special.execute(cur, sql):\n  File "/usr/local/lib/python3.8/site-packages/litecli/packages/special/main.py", line 109, in execute\n    raise CommandNotFound\nlitecli.packages.special.main.CommandNotFound\n\nDuring handling of the above exception, another exception occurred:\n\nTraceback (most recent call last):\n  File "/usr/local/lib/python3.8/site-packages/litecli/main.py", line 441, in one_iteration\n    for title, cur, headers, status in res:\n  File "/usr/local/lib/python3.8/site-packages/litecli/sqlexecute.py", line 125, in run\n    cur.execute(sql)\nsqlite3.OperationalError: near "ex": syntax error\n'
2020-11-19 13:28:17,955 (2146/MainThread) litecli.main ERROR - sql: '.ta', error: OperationalError('near ".": syntax error')
2020-11-19 13:28:17,956 (2146/MainThread) litecli.main ERROR - traceback: 'Traceback (most recent call last):\n  File "/usr/local/lib/python3.8/site-packages/litecli/sqlexecute.py", line 121, in run\n    for result in special.execute(cur, sql):\n  File "/usr/local/lib/python3.8/site-packages/litecli/packages/special/main.py", line 109, in execute\n    raise CommandNotFound\nlitecli.packages.special.main.CommandNotFound\n\nDuring handling of the above exception, another exception occurred:\n\nTraceback (most recent call last):\n  File "/usr/local/lib/python3.8/site-packages/litecli/main.py", line 441, in one_iteration\n    for title, cur, headers, status in res:\n  File "/usr/local/lib/python3.8/site-packages/litecli/sqlexecute.py", line 125, in run\n    cur.execute(sql)\nsqlite3.OperationalError: near ".": syntax error\n'
2020-11-19 13:37:20,397 (3020/MainThread) litecli.main ERROR - sql: 'us', error: OperationalError('near "us": syntax error')
2020-11-19 13:37:20,398 (3020/MainThread) litecli.main ERROR - traceback: 'Traceback (most recent call last):\n  File "/usr/local/lib/python3.8/site-packages/litecli/sqlexecute.py", line 121, in run\n    for result in special.execute(cur, sql):\n  File "/usr/local/lib/python3.8/site-packages/litecli/packages/special/main.py", line 109, in execute\n    raise CommandNotFound\nlitecli.packages.special.main.CommandNotFound\n\nDuring handling of the above exception, another exception occurred:\n\nTraceback (most recent call last):\n  File "/usr/local/lib/python3.8/site-packages/litecli/main.py", line 441, in one_iteration\n    for title, cur, headers, status in res:\n  File "/usr/local/lib/python3.8/site-packages/litecli/sqlexecute.py", line 125, in run\n    cur.execute(sql)\nsqlite3.OperationalError: near "us": syntax error\n'
2020-11-19 13:39:07,803 (3020/MainThread) litecli.main ERROR - sql: 'insert into student(student_id,name,sex,grade,address,admission_year,gpa,credit)', error: OperationalError('incomplete input')
2020-11-19 13:39:07,803 (3020/MainThread) litecli.main ERROR - traceback: 'Traceback (most recent call last):\n  File "/usr/local/lib/python3.8/site-packages/litecli/sqlexecute.py", line 121, in run\n    for result in special.execute(cur, sql):\n  File "/usr/local/lib/python3.8/site-packages/litecli/packages/special/main.py", line 109, in execute\n    raise CommandNotFound\nlitecli.packages.special.main.CommandNotFound\n\nDuring handling of the above exception, another exception occurred:\n\nTraceback (most recent call last):\n  File "/usr/local/lib/python3.8/site-packages/litecli/main.py", line 441, in one_iteration\n    for title, cur, headers, status in res:\n  File "/usr/local/lib/python3.8/site-packages/litecli/sqlexecute.py", line 125, in run\n    cur.execute(sql)\nsqlite3.OperationalError: incomplete input\n'
2020-11-19 13:51:45,434 (3020/MainThread) litecli.main ERROR - sql: '.separator', error: OperationalError('near ".": syntax error')
2020-11-19 13:51:45,435 (3020/MainThread) litecli.main ERROR - traceback: 'Traceback (most recent call last):\n  File "/usr/local/lib/python3.8/site-packages/litecli/sqlexecute.py", line 121, in run\n    for result in special.execute(cur, sql):\n  File "/usr/local/lib/python3.8/site-packages/litecli/packages/special/main.py", line 109, in execute\n    raise CommandNotFound\nlitecli.packages.special.main.CommandNotFound\n\nDuring handling of the above exception, another exception occurred:\n\nTraceback (most recent call last):\n  File "/usr/local/lib/python3.8/site-packages/litecli/main.py", line 441, in one_iteration\n    for title, cur, headers, status in res:\n  File "/usr/local/lib/python3.8/site-packages/litecli/sqlexecute.py", line 125, in run\n    cur.execute(sql)\nsqlite3.OperationalError: near ".": syntax error\n'
2020-11-19 14:12:33,854 (3020/MainThread) litecli.main ERROR - sql: 'delete from student where name=竹本 武雄', error: OperationalError('near "武雄": syntax error')
2020-11-19 14:12:33,855 (3020/MainThread) litecli.main ERROR - traceback: 'Traceback (most recent call last):\n  File "/usr/local/lib/python3.8/site-packages/litecli/sqlexecute.py", line 121, in run\n    for result in special.execute(cur, sql):\n  File "/usr/local/lib/python3.8/site-packages/litecli/packages/special/main.py", line 109, in execute\n    raise CommandNotFound\nlitecli.packages.special.main.CommandNotFound\n\nDuring handling of the above exception, another exception occurred:\n\nTraceback (most recent call last):\n  File "/usr/local/lib/python3.8/site-packages/litecli/main.py", line 441, in one_iteration\n    for title, cur, headers, status in res:\n  File "/usr/local/lib/python3.8/site-packages/litecli/sqlexecute.py", line 125, in run\n    cur.execute(sql)\nsqlite3.OperationalError: near "武雄": syntax error\n'
2020-11-19 14:13:48,274 (3020/MainThread) litecli.main ERROR - sql: 'delete from student where student_id=J10327', error: OperationalError('no such column: J10327')
2020-11-19 14:13:48,274 (3020/MainThread) litecli.main ERROR - traceback: 'Traceback (most recent call last):\n  File "/usr/local/lib/python3.8/site-packages/litecli/sqlexecute.py", line 121, in run\n    for result in special.execute(cur, sql):\n  File "/usr/local/lib/python3.8/site-packages/litecli/packages/special/main.py", line 109, in execute\n    raise CommandNotFound\nlitecli.packages.special.main.CommandNotFound\n\nDuring handling of the above exception, another exception occurred:\n\nTraceback (most recent call last):\n  File "/usr/local/lib/python3.8/site-packages/litecli/main.py", line 441, in one_iteration\n    for title, cur, headers, status in res:\n  File "/usr/local/lib/python3.8/site-packages/litecli/sqlexecute.py", line 125, in run\n    cur.execute(sql)\nsqlite3.OperationalError: no such column: J10327\n'
2020-11-19 14:14:46,921 (3020/MainThread) litecli.main ERROR - sql: 'delete from student where student_id = <U+FEFF>J10327', error: OperationalError('near "<": syntax error')
2020-11-19 14:14:46,922 (3020/MainThread) litecli.main ERROR - traceback: 'Traceback (most recent call last):\n  File "/usr/local/lib/python3.8/site-packages/litecli/sqlexecute.py", line 121, in run\n    for result in special.execute(cur, sql):\n  File "/usr/local/lib/python3.8/site-packages/litecli/packages/special/main.py", line 109, in execute\n    raise CommandNotFound\nlitecli.packages.special.main.CommandNotFound\n\nDuring handling of the above exception, another exception occurred:\n\nTraceback (most recent call last):\n  File "/usr/local/lib/python3.8/site-packages/litecli/main.py", line 441, in one_iteration\n    for title, cur, headers, status in res:\n  File "/usr/local/lib/python3.8/site-packages/litecli/sqlexecute.py", line 125, in run\n    cur.execute(sql)\nsqlite3.OperationalError: near "<": syntax error\n'
2020-11-19 14:16:08,409 (3020/MainThread) litecli.main ERROR - sql: 'delete from student where address=千葉県香取市石納2-4', error: OperationalError('no such column: 千葉県香取市石納2')
2020-11-19 14:16:08,409 (3020/MainThread) litecli.main ERROR - traceback: 'Traceback (most recent call last):\n  File "/usr/local/lib/python3.8/site-packages/litecli/sqlexecute.py", line 121, in run\n    for result in special.execute(cur, sql):\n  File "/usr/local/lib/python3.8/site-packages/litecli/packages/special/main.py", line 109, in execute\n    raise CommandNotFound\nlitecli.packages.special.main.CommandNotFound\n\nDuring handling of the above exception, another exception occurred:\n\nTraceback (most recent call last):\n  File "/usr/local/lib/python3.8/site-packages/litecli/main.py", line 441, in one_iteration\n    for title, cur, headers, status in res:\n  File "/usr/local/lib/python3.8/site-packages/litecli/sqlexecute.py", line 125, in run\n    cur.execute(sql)\nsqlite3.OperationalError: no such column: 千葉県香取市石納2\n'
2020-11-19 14:16:46,140 (3020/MainThread) litecli.main ERROR - sql: 'delete from student where name=竹本 武雄', error: OperationalError('near "武雄": syntax error')
2020-11-19 14:16:46,141 (3020/MainThread) litecli.main ERROR - traceback: 'Traceback (most recent call last):\n  File "/usr/local/lib/python3.8/site-packages/litecli/sqlexecute.py", line 121, in run\n    for result in special.execute(cur, sql):\n  File "/usr/local/lib/python3.8/site-packages/litecli/packages/special/main.py", line 109, in execute\n    raise CommandNotFound\nlitecli.packages.special.main.CommandNotFound\n\nDuring handling of the above exception, another exception occurred:\n\nTraceback (most recent call last):\n  File "/usr/local/lib/python3.8/site-packages/litecli/main.py", line 441, in one_iteration\n    for title, cur, headers, status in res:\n  File "/usr/local/lib/python3.8/site-packages/litecli/sqlexecute.py", line 125, in run\n    cur.execute(sql)\nsqlite3.OperationalError: near "武雄": syntax error\n'
2020-11-19 14:17:14,176 (3020/MainThread) litecli.main ERROR - sql: 'delete from student where name=竹本', error: OperationalError('no such column: 竹本')
2020-11-19 14:17:14,176 (3020/MainThread) litecli.main ERROR - traceback: 'Traceback (most recent call last):\n  File "/usr/local/lib/python3.8/site-packages/litecli/sqlexecute.py", line 121, in run\n    for result in special.execute(cur, sql):\n  File "/usr/local/lib/python3.8/site-packages/litecli/packages/special/main.py", line 109, in execute\n    raise CommandNotFound\nlitecli.packages.special.main.CommandNotFound\n\nDuring handling of the above exception, another exception occurred:\n\nTraceback (most recent call last):\n  File "/usr/local/lib/python3.8/site-packages/litecli/main.py", line 441, in one_iteration\n    for title, cur, headers, status in res:\n  File "/usr/local/lib/python3.8/site-packages/litecli/sqlexecute.py", line 125, in run\n    cur.execute(sql)\nsqlite3.OperationalError: no such column: 竹本\n'
2020-11-19 14:37:57,472 (4320/MainThread) litecli.main ERROR - sql: '.exit', error: OperationalError('Not connected to database.')
2020-11-19 14:37:57,475 (4320/MainThread) litecli.main ERROR - traceback: 'Traceback (most recent call last):\n  File "/usr/local/lib/python3.8/site-packages/litecli/main.py", line 441, in one_iteration\n    for title, cur, headers, status in res:\n  File "/usr/local/lib/python3.8/site-packages/litecli/sqlexecute.py", line 114, in run\n    raise OperationalError("Not connected to database.")\nsqlite3.OperationalError: Not connected to database.\n'
2020-11-19 14:38:05,683 (4320/MainThread) litecli.main ERROR - sql: '.exit', error: OperationalError('Not connected to database.')
2020-11-19 14:38:05,684 (4320/MainThread) litecli.main ERROR - traceback: 'Traceback (most recent call last):\n  File "/usr/local/lib/python3.8/site-packages/litecli/main.py", line 441, in one_iteration\n    for title, cur, headers, status in res:\n  File "/usr/local/lib/python3.8/site-packages/litecli/sqlexecute.py", line 114, in run\n    raise OperationalError("Not connected to database.")\nsqlite3.OperationalError: Not connected to database.\n'
2020-11-19 14:38:49,536 (4505/MainThread) litecli.main ERROR - sql: 'ls', error: OperationalError('near "ls": syntax error')
2020-11-19 14:38:49,537 (4505/MainThread) litecli.main ERROR - traceback: 'Traceback (most recent call last):\n  File "/usr/local/lib/python3.8/site-packages/litecli/sqlexecute.py", line 121, in run\n    for result in special.execute(cur, sql):\n  File "/usr/local/lib/python3.8/site-packages/litecli/packages/special/main.py", line 109, in execute\n    raise CommandNotFound\nlitecli.packages.special.main.CommandNotFound\n\nDuring handling of the above exception, another exception occurred:\n\nTraceback (most recent call last):\n  File "/usr/local/lib/python3.8/site-packages/litecli/main.py", line 441, in one_iteration\n    for title, cur, headers, status in res:\n  File "/usr/local/lib/python3.8/site-packages/litecli/sqlexecute.py", line 125, in run\n    cur.execute(sql)\nsqlite3.OperationalError: near "ls": syntax error\n'
2020-11-19 14:40:40,289 (4505/MainThread) litecli.main ERROR - sql: 'explain', error: OperationalError('incomplete input')
2020-11-19 14:40:40,289 (4505/MainThread) litecli.main ERROR - traceback: 'Traceback (most recent call last):\n  File "/usr/local/lib/python3.8/site-packages/litecli/sqlexecute.py", line 121, in run\n    for result in special.execute(cur, sql):\n  File "/usr/local/lib/python3.8/site-packages/litecli/packages/special/main.py", line 109, in execute\n    raise CommandNotFound\nlitecli.packages.special.main.CommandNotFound\n\nDuring handling of the above exception, another exception occurred:\n\nTraceback (most recent call last):\n  File "/usr/local/lib/python3.8/site-packages/litecli/main.py", line 441, in one_iteration\n    for title, cur, headers, status in res:\n  File "/usr/local/lib/python3.8/site-packages/litecli/sqlexecute.py", line 125, in run\n    cur.execute(sql)\nsqlite3.OperationalError: incomplete input\n'
2020-11-19 14:48:19,287 (4505/MainThread) litecli.main ERROR - sql: '.exiy', error: OperationalError('near ".": syntax error')
2020-11-19 14:48:19,288 (4505/MainThread) litecli.main ERROR - traceback: 'Traceback (most recent call last):\n  File "/usr/local/lib/python3.8/site-packages/litecli/sqlexecute.py", line 121, in run\n    for result in special.execute(cur, sql):\n  File "/usr/local/lib/python3.8/site-packages/litecli/packages/special/main.py", line 109, in execute\n    raise CommandNotFound\nlitecli.packages.special.main.CommandNotFound\n\nDuring handling of the above exception, another exception occurred:\n\nTraceback (most recent call last):\n  File "/usr/local/lib/python3.8/site-packages/litecli/main.py", line 441, in one_iteration\n    for title, cur, headers, status in res:\n  File "/usr/local/lib/python3.8/site-packages/litecli/sqlexecute.py", line 125, in run\n    cur.execute(sql)\nsqlite3.OperationalError: near ".": syntax error\n'
2020-11-26 13:17:53,035 (92877/MainThread) litecli.main ERROR - sql: 'tables', error: OperationalError('near "tables": syntax error')
2020-11-26 13:17:53,038 (92877/MainThread) litecli.main ERROR - traceback: 'Traceback (most recent call last):\n  File "/usr/local/lib/python3.8/site-packages/litecli/sqlexecute.py", line 121, in run\n    for result in special.execute(cur, sql):\n  File "/usr/local/lib/python3.8/site-packages/litecli/packages/special/main.py", line 109, in execute\n    raise CommandNotFound\nlitecli.packages.special.main.CommandNotFound\n\nDuring handling of the above exception, another exception occurred:\n\nTraceback (most recent call last):\n  File "/usr/local/lib/python3.8/site-packages/litecli/main.py", line 441, in one_iteration\n    for title, cur, headers, status in res:\n  File "/usr/local/lib/python3.8/site-packages/litecli/sqlexecute.py", line 125, in run\n    cur.execute(sql)\nsqlite3.OperationalError: near "tables": syntax error\n'
2020-11-26 13:18:52,361 (92877/MainThread) litecli.main ERROR - sql: '.explain', error: OperationalError('near ".": syntax error')
2020-11-26 13:18:52,363 (92877/MainThread) litecli.main ERROR - traceback: 'Traceback (most recent call last):\n  File "/usr/local/lib/python3.8/site-packages/litecli/sqlexecute.py", line 121, in run\n    for result in special.execute(cur, sql):\n  File "/usr/local/lib/python3.8/site-packages/litecli/packages/special/main.py", line 109, in execute\n    raise CommandNotFound\nlitecli.packages.special.main.CommandNotFound\n\nDuring handling of the above exception, another exception occurred:\n\nTraceback (most recent call last):\n  File "/usr/local/lib/python3.8/site-packages/litecli/main.py", line 441, in one_iteration\n    for title, cur, headers, status in res:\n  File "/usr/local/lib/python3.8/site-packages/litecli/sqlexecute.py", line 125, in run\n    cur.execute(sql)\nsqlite3.OperationalError: near ".": syntax error\n'
2020-11-26 13:18:58,724 (92877/MainThread) litecli.main ERROR - sql: 'explain', error: OperationalError('incomplete input')
2020-11-26 13:18:58,725 (92877/MainThread) litecli.main ERROR - traceback: 'Traceback (most recent call last):\n  File "/usr/local/lib/python3.8/site-packages/litecli/sqlexecute.py", line 121, in run\n    for result in special.execute(cur, sql):\n  File "/usr/local/lib/python3.8/site-packages/litecli/packages/special/main.py", line 109, in execute\n    raise CommandNotFound\nlitecli.packages.special.main.CommandNotFound\n\nDuring handling of the above exception, another exception occurred:\n\nTraceback (most recent call last):\n  File "/usr/local/lib/python3.8/site-packages/litecli/main.py", line 441, in one_iteration\n    for title, cur, headers, status in res:\n  File "/usr/local/lib/python3.8/site-packages/litecli/sqlexecute.py", line 125, in run\n    cur.execute(sql)\nsqlite3.OperationalError: incomplete input\n'
2020-11-26 13:19:19,561 (92877/MainThread) litecli.main ERROR - sql: 'tables', error: OperationalError('near "tables": syntax error')
2020-11-26 13:19:19,561 (92877/MainThread) litecli.main ERROR - traceback: 'Traceback (most recent call last):\n  File "/usr/local/lib/python3.8/site-packages/litecli/sqlexecute.py", line 121, in run\n    for result in special.execute(cur, sql):\n  File "/usr/local/lib/python3.8/site-packages/litecli/packages/special/main.py", line 109, in execute\n    raise CommandNotFound\nlitecli.packages.special.main.CommandNotFound\n\nDuring handling of the above exception, another exception occurred:\n\nTraceback (most recent call last):\n  File "/usr/local/lib/python3.8/site-packages/litecli/main.py", line 441, in one_iteration\n    for title, cur, headers, status in res:\n  File "/usr/local/lib/python3.8/site-packages/litecli/sqlexecute.py", line 125, in run\n    cur.execute(sql)\nsqlite3.OperationalError: near "tables": syntax error\n'
2020-11-26 14:31:37,473 (93258/MainThread) litecli.main ERROR - sql: '.ex', error: OperationalError('near ".": syntax error')
2020-11-26 14:31:37,478 (93258/MainThread) litecli.main ERROR - traceback: 'Traceback (most recent call last):\n  File "/usr/local/lib/python3.8/site-packages/litecli/sqlexecute.py", line 121, in run\n    for result in special.execute(cur, sql):\n  File "/usr/local/lib/python3.8/site-packages/litecli/packages/special/main.py", line 109, in execute\n    raise CommandNotFound\nlitecli.packages.special.main.CommandNotFound\n\nDuring handling of the above exception, another exception occurred:\n\nTraceback (most recent call last):\n  File "/usr/local/lib/python3.8/site-packages/litecli/main.py", line 441, in one_iteration\n    for title, cur, headers, status in res:\n  File "/usr/local/lib/python3.8/site-packages/litecli/sqlexecute.py", line 125, in run\n    cur.execute(sql)\nsqlite3.OperationalError: near ".": syntax error\n'
2020-12-03 13:17:31,470 (63153/MainThread) litecli.main ERROR - sql: '.explain', error: OperationalError('near ".": syntax error')
2020-12-03 13:17:31,475 (63153/MainThread) litecli.main ERROR - traceback: 'Traceback (most recent call last):\n  File "/usr/local/lib/python3.8/site-packages/litecli/sqlexecute.py", line 121, in run\n    for result in special.execute(cur, sql):\n  File "/usr/local/lib/python3.8/site-packages/litecli/packages/special/main.py", line 109, in execute\n    raise CommandNotFound\nlitecli.packages.special.main.CommandNotFound\n\nDuring handling of the above exception, another exception occurred:\n\nTraceback (most recent call last):\n  File "/usr/local/lib/python3.8/site-packages/litecli/main.py", line 441, in one_iteration\n    for title, cur, headers, status in res:\n  File "/usr/local/lib/python3.8/site-packages/litecli/sqlexecute.py", line 125, in run\n    cur.execute(sql)\nsqlite3.OperationalError: near ".": syntax error\n'
2020-12-03 13:17:36,230 (63153/MainThread) litecli.main ERROR - sql: 'explain', error: OperationalError('incomplete input')
2020-12-03 13:17:36,230 (63153/MainThread) litecli.main ERROR - traceback: 'Traceback (most recent call last):\n  File "/usr/local/lib/python3.8/site-packages/litecli/sqlexecute.py", line 121, in run\n    for result in special.execute(cur, sql):\n  File "/usr/local/lib/python3.8/site-packages/litecli/packages/special/main.py", line 109, in execute\n    raise CommandNotFound\nlitecli.packages.special.main.CommandNotFound\n\nDuring handling of the above exception, another exception occurred:\n\nTraceback (most recent call last):\n  File "/usr/local/lib/python3.8/site-packages/litecli/main.py", line 441, in one_iteration\n    for title, cur, headers, status in res:\n  File "/usr/local/lib/python3.8/site-packages/litecli/sqlexecute.py", line 125, in run\n    cur.execute(sql)\nsqlite3.OperationalError: incomplete input\n'
2020-12-03 13:22:25,379 (63153/MainThread) litecli.main ERROR - sql: '.backup tuis.bk', error: OperationalError('near ".": syntax error')
2020-12-03 13:22:25,380 (63153/MainThread) litecli.main ERROR - traceback: 'Traceback (most recent call last):\n  File "/usr/local/lib/python3.8/site-packages/litecli/sqlexecute.py", line 121, in run\n    for result in special.execute(cur, sql):\n  File "/usr/local/lib/python3.8/site-packages/litecli/packages/special/main.py", line 109, in execute\n    raise CommandNotFound\nlitecli.packages.special.main.CommandNotFound\n\nDuring handling of the above exception, another exception occurred:\n\nTraceback (most recent call last):\n  File "/usr/local/lib/python3.8/site-packages/litecli/main.py", line 441, in one_iteration\n    for title, cur, headers, status in res:\n  File "/usr/local/lib/python3.8/site-packages/litecli/sqlexecute.py", line 125, in run\n    cur.execute(sql)\nsqlite3.OperationalError: near ".": syntax error\n'
2020-12-03 13:22:37,347 (63153/MainThread) litecli.main ERROR - sql: 'backup tuis.bk', error: OperationalError('near "backup": syntax error')
2020-12-03 13:22:37,348 (63153/MainThread) litecli.main ERROR - traceback: 'Traceback (most recent call last):\n  File "/usr/local/lib/python3.8/site-packages/litecli/sqlexecute.py", line 121, in run\n    for result in special.execute(cur, sql):\n  File "/usr/local/lib/python3.8/site-packages/litecli/packages/special/main.py", line 109, in execute\n    raise CommandNotFound\nlitecli.packages.special.main.CommandNotFound\n\nDuring handling of the above exception, another exception occurred:\n\nTraceback (most recent call last):\n  File "/usr/local/lib/python3.8/site-packages/litecli/main.py", line 441, in one_iteration\n    for title, cur, headers, status in res:\n  File "/usr/local/lib/python3.8/site-packages/litecli/sqlexecute.py", line 125, in run\n    cur.execute(sql)\nsqlite3.OperationalError: near "backup": syntax error\n'
2020-12-03 13:23:05,777 (63153/MainThread) litecli.main ERROR - sql: 'backup  tuis11.bk', error: OperationalError('near "backup": syntax error')
2020-12-03 13:23:05,778 (63153/MainThread) litecli.main ERROR - traceback: 'Traceback (most recent call last):\n  File "/usr/local/lib/python3.8/site-packages/litecli/sqlexecute.py", line 121, in run\n    for result in special.execute(cur, sql):\n  File "/usr/local/lib/python3.8/site-packages/litecli/packages/special/main.py", line 109, in execute\n    raise CommandNotFound\nlitecli.packages.special.main.CommandNotFound\n\nDuring handling of the above exception, another exception occurred:\n\nTraceback (most recent call last):\n  File "/usr/local/lib/python3.8/site-packages/litecli/main.py", line 441, in one_iteration\n    for title, cur, headers, status in res:\n  File "/usr/local/lib/python3.8/site-packages/litecli/sqlexecute.py", line 125, in run\n    cur.execute(sql)\nsqlite3.OperationalError: near "backup": syntax error\n'
2020-12-03 13:23:10,267 (63153/MainThread) litecli.main ERROR - sql: '.backup tuis.bk', error: OperationalError('near ".": syntax error')
2020-12-03 13:23:10,267 (63153/MainThread) litecli.main ERROR - traceback: 'Traceback (most recent call last):\n  File "/usr/local/lib/python3.8/site-packages/litecli/sqlexecute.py", line 121, in run\n    for result in special.execute(cur, sql):\n  File "/usr/local/lib/python3.8/site-packages/litecli/packages/special/main.py", line 109, in execute\n    raise CommandNotFound\nlitecli.packages.special.main.CommandNotFound\n\nDuring handling of the above exception, another exception occurred:\n\nTraceback (most recent call last):\n  File "/usr/local/lib/python3.8/site-packages/litecli/main.py", line 441, in one_iteration\n    for title, cur, headers, status in res:\n  File "/usr/local/lib/python3.8/site-packages/litecli/sqlexecute.py", line 125, in run\n    cur.execute(sql)\nsqlite3.OperationalError: near ".": syntax error\n'
2020-12-03 13:30:39,712 (63153/MainThread) litecli.main ERROR - sql: 'se', error: OperationalError('near "se": syntax error')
2020-12-03 13:30:39,713 (63153/MainThread) litecli.main ERROR - traceback: 'Traceback (most recent call last):\n  File "/usr/local/lib/python3.8/site-packages/litecli/sqlexecute.py", line 121, in run\n    for result in special.execute(cur, sql):\n  File "/usr/local/lib/python3.8/site-packages/litecli/packages/special/main.py", line 109, in execute\n    raise CommandNotFound\nlitecli.packages.special.main.CommandNotFound\n\nDuring handling of the above exception, another exception occurred:\n\nTraceback (most recent call last):\n  File "/usr/local/lib/python3.8/site-packages/litecli/main.py", line 441, in one_iteration\n    for title, cur, headers, status in res:\n  File "/usr/local/lib/python3.8/site-packages/litecli/sqlexecute.py", line 125, in run\n    cur.execute(sql)\nsqlite3.OperationalError: near "se": syntax error\n'
2020-12-03 13:30:49,598 (63153/MainThread) litecli.main ERROR - sql: 'select * from ', error: OperationalError('incomplete input')
2020-12-03 13:30:49,599 (63153/MainThread) litecli.main ERROR - traceback: 'Traceback (most recent call last):\n  File "/usr/local/lib/python3.8/site-packages/litecli/sqlexecute.py", line 121, in run\n    for result in special.execute(cur, sql):\n  File "/usr/local/lib/python3.8/site-packages/litecli/packages/special/main.py", line 109, in execute\n    raise CommandNotFound\nlitecli.packages.special.main.CommandNotFound\n\nDuring handling of the above exception, another exception occurred:\n\nTraceback (most recent call last):\n  File "/usr/local/lib/python3.8/site-packages/litecli/main.py", line 441, in one_iteration\n    for title, cur, headers, status in res:\n  File "/usr/local/lib/python3.8/site-packages/litecli/sqlexecute.py", line 125, in run\n    cur.execute(sql)\nsqlite3.OperationalError: incomplete input\n'
2020-12-03 13:31:38,349 (63153/MainThread) litecli.main ERROR - sql: 'select * from student where name address li', error: OperationalError('near "address": syntax error')
2020-12-03 13:31:38,349 (63153/MainThread) litecli.main ERROR - traceback: 'Traceback (most recent call last):\n  File "/usr/local/lib/python3.8/site-packages/litecli/sqlexecute.py", line 121, in run\n    for result in special.execute(cur, sql):\n  File "/usr/local/lib/python3.8/site-packages/litecli/packages/special/main.py", line 109, in execute\n    raise CommandNotFound\nlitecli.packages.special.main.CommandNotFound\n\nDuring handling of the above exception, another exception occurred:\n\nTraceback (most recent call last):\n  File "/usr/local/lib/python3.8/site-packages/litecli/main.py", line 441, in one_iteration\n    for title, cur, headers, status in res:\n  File "/usr/local/lib/python3.8/site-packages/litecli/sqlexecute.py", line 125, in run\n    cur.execute(sql)\nsqlite3.OperationalError: near "address": syntax error\n'
2020-12-03 13:32:01,526 (63153/MainThread) litecli.main ERROR - sql: "select * from student where name address like '%千葉%'", error: OperationalError('near "address": syntax error')
2020-12-03 13:32:01,526 (63153/MainThread) litecli.main ERROR - traceback: 'Traceback (most recent call last):\n  File "/usr/local/lib/python3.8/site-packages/litecli/sqlexecute.py", line 121, in run\n    for result in special.execute(cur, sql):\n  File "/usr/local/lib/python3.8/site-packages/litecli/packages/special/main.py", line 109, in execute\n    raise CommandNotFound\nlitecli.packages.special.main.CommandNotFound\n\nDuring handling of the above exception, another exception occurred:\n\nTraceback (most recent call last):\n  File "/usr/local/lib/python3.8/site-packages/litecli/main.py", line 441, in one_iteration\n    for title, cur, headers, status in res:\n  File "/usr/local/lib/python3.8/site-packages/litecli/sqlexecute.py", line 125, in run\n    cur.execute(sql)\nsqlite3.OperationalError: near "address": syntax error\n'
2020-12-03 13:53:04,128 (63153/MainThread) litecli.main ERROR - sql: 'select * from student where sex = 女 or', error: OperationalError('incomplete input')
2020-12-03 13:53:04,130 (63153/MainThread) litecli.main ERROR - traceback: 'Traceback (most recent call last):\n  File "/usr/local/lib/python3.8/site-packages/litecli/sqlexecute.py", line 121, in run\n    for result in special.execute(cur, sql):\n  File "/usr/local/lib/python3.8/site-packages/litecli/packages/special/main.py", line 109, in execute\n    raise CommandNotFound\nlitecli.packages.special.main.CommandNotFound\n\nDuring handling of the above exception, another exception occurred:\n\nTraceback (most recent call last):\n  File "/usr/local/lib/python3.8/site-packages/litecli/main.py", line 441, in one_iteration\n    for title, cur, headers, status in res:\n  File "/usr/local/lib/python3.8/site-packages/litecli/sqlexecute.py", line 125, in run\n    cur.execute(sql)\nsqlite3.OperationalError: incomplete input\n'
2020-12-03 13:53:23,937 (63153/MainThread) litecli.main ERROR - sql: 'select * from student where sex = 女 order by gpa ', error: OperationalError('no such column: 女')
2020-12-03 13:53:23,937 (63153/MainThread) litecli.main ERROR - traceback: 'Traceback (most recent call last):\n  File "/usr/local/lib/python3.8/site-packages/litecli/sqlexecute.py", line 121, in run\n    for result in special.execute(cur, sql):\n  File "/usr/local/lib/python3.8/site-packages/litecli/packages/special/main.py", line 109, in execute\n    raise CommandNotFound\nlitecli.packages.special.main.CommandNotFound\n\nDuring handling of the above exception, another exception occurred:\n\nTraceback (most recent call last):\n  File "/usr/local/lib/python3.8/site-packages/litecli/main.py", line 441, in one_iteration\n    for title, cur, headers, status in res:\n  File "/usr/local/lib/python3.8/site-packages/litecli/sqlexecute.py", line 125, in run\n    cur.execute(sql)\nsqlite3.OperationalError: no such column: 女\n'
2020-12-03 13:53:33,366 (63153/MainThread) litecli.main ERROR - sql: 'select * from student where sex = 女 order by gpa ', error: OperationalError('no such column: 女')
2020-12-03 13:53:33,367 (63153/MainThread) litecli.main ERROR - traceback: 'Traceback (most recent call last):\n  File "/usr/local/lib/python3.8/site-packages/litecli/sqlexecute.py", line 121, in run\n    for result in special.execute(cur, sql):\n  File "/usr/local/lib/python3.8/site-packages/litecli/packages/special/main.py", line 109, in execute\n    raise CommandNotFound\nlitecli.packages.special.main.CommandNotFound\n\nDuring handling of the above exception, another exception occurred:\n\nTraceback (most recent call last):\n  File "/usr/local/lib/python3.8/site-packages/litecli/main.py", line 441, in one_iteration\n    for title, cur, headers, status in res:\n  File "/usr/local/lib/python3.8/site-packages/litecli/sqlexecute.py", line 125, in run\n    cur.execute(sql)\nsqlite3.OperationalError: no such column: 女\n'
2020-12-03 20:03:11,344 (74428/MainThread) litecli.main ERROR - sql: 'tables', error: OperationalError('near "tables": syntax error')
2020-12-03 20:03:11,349 (74428/MainThread) litecli.main ERROR - traceback: 'Traceback (most recent call last):\n  File "/usr/local/lib/python3.8/site-packages/litecli/sqlexecute.py", line 121, in run\n    for result in special.execute(cur, sql):\n  File "/usr/local/lib/python3.8/site-packages/litecli/packages/special/main.py", line 109, in execute\n    raise CommandNotFound\nlitecli.packages.special.main.CommandNotFound\n\nDuring handling of the above exception, another exception occurred:\n\nTraceback (most recent call last):\n  File "/usr/local/lib/python3.8/site-packages/litecli/main.py", line 441, in one_iteration\n    for title, cur, headers, status in res:\n  File "/usr/local/lib/python3.8/site-packages/litecli/sqlexecute.py", line 125, in run\n    cur.execute(sql)\nsqlite3.OperationalError: near "tables": syntax error\n'
2020-12-03 20:03:26,886 (74428/MainThread) litecli.main ERROR - sql: 'explain', error: OperationalError('incomplete input')
2020-12-03 20:03:26,887 (74428/MainThread) litecli.main ERROR - traceback: 'Traceback (most recent call last):\n  File "/usr/local/lib/python3.8/site-packages/litecli/sqlexecute.py", line 121, in run\n    for result in special.execute(cur, sql):\n  File "/usr/local/lib/python3.8/site-packages/litecli/packages/special/main.py", line 109, in execute\n    raise CommandNotFound\nlitecli.packages.special.main.CommandNotFound\n\nDuring handling of the above exception, another exception occurred:\n\nTraceback (most recent call last):\n  File "/usr/local/lib/python3.8/site-packages/litecli/main.py", line 441, in one_iteration\n    for title, cur, headers, status in res:\n  File "/usr/local/lib/python3.8/site-packages/litecli/sqlexecute.py", line 125, in run\n    cur.execute(sql)\nsqlite3.OperationalError: incomplete input\n'
2020-12-03 20:04:04,608 (74428/MainThread) litecli.main ERROR - sql: 'exi', error: OperationalError('near "exi": syntax error')
2020-12-03 20:04:04,609 (74428/MainThread) litecli.main ERROR - traceback: 'Traceback (most recent call last):\n  File "/usr/local/lib/python3.8/site-packages/litecli/sqlexecute.py", line 121, in run\n    for result in special.execute(cur, sql):\n  File "/usr/local/lib/python3.8/site-packages/litecli/packages/special/main.py", line 109, in execute\n    raise CommandNotFound\nlitecli.packages.special.main.CommandNotFound\n\nDuring handling of the above exception, another exception occurred:\n\nTraceback (most recent call last):\n  File "/usr/local/lib/python3.8/site-packages/litecli/main.py", line 441, in one_iteration\n    for title, cur, headers, status in res:\n  File "/usr/local/lib/python3.8/site-packages/litecli/sqlexecute.py", line 125, in run\n    cur.execute(sql)\nsqlite3.OperationalError: near "exi": syntax error\n'
2020-12-03 20:04:07,113 (74428/MainThread) litecli.main ERROR - sql: 'ex', error: OperationalError('near "ex": syntax error')
2020-12-03 20:04:07,114 (74428/MainThread) litecli.main ERROR - traceback: 'Traceback (most recent call last):\n  File "/usr/local/lib/python3.8/site-packages/litecli/sqlexecute.py", line 121, in run\n    for result in special.execute(cur, sql):\n  File "/usr/local/lib/python3.8/site-packages/litecli/packages/special/main.py", line 109, in execute\n    raise CommandNotFound\nlitecli.packages.special.main.CommandNotFound\n\nDuring handling of the above exception, another exception occurred:\n\nTraceback (most recent call last):\n  File "/usr/local/lib/python3.8/site-packages/litecli/main.py", line 441, in one_iteration\n    for title, cur, headers, status in res:\n  File "/usr/local/lib/python3.8/site-packages/litecli/sqlexecute.py", line 125, in run\n    cur.execute(sql)\nsqlite3.OperationalError: near "ex": syntax error\n'
2020-12-10 13:34:01,364 (69844/MainThread) litecli.main ERROR - sql: 'tables', error: OperationalError('near "tables": syntax error')
2020-12-10 13:34:01,366 (69844/MainThread) litecli.main ERROR - traceback: 'Traceback (most recent call last):\n  File "/usr/local/lib/python3.9/site-packages/litecli/sqlexecute.py", line 121, in run\n    for result in special.execute(cur, sql):\n  File "/usr/local/lib/python3.9/site-packages/litecli/packages/special/main.py", line 109, in execute\n    raise CommandNotFound\nlitecli.packages.special.main.CommandNotFound\n\nDuring handling of the above exception, another exception occurred:\n\nTraceback (most recent call last):\n  File "/usr/local/lib/python3.9/site-packages/litecli/main.py", line 441, in one_iteration\n    for title, cur, headers, status in res:\n  File "/usr/local/lib/python3.9/site-packages/litecli/sqlexecute.py", line 125, in run\n    cur.execute(sql)\nsqlite3.OperationalError: near "tables": syntax error\n'
2020-12-10 13:34:10,360 (69844/MainThread) litecli.main ERROR - sql: 'table', error: OperationalError('near "table": syntax error')
2020-12-10 13:34:10,361 (69844/MainThread) litecli.main ERROR - traceback: 'Traceback (most recent call last):\n  File "/usr/local/lib/python3.9/site-packages/litecli/sqlexecute.py", line 121, in run\n    for result in special.execute(cur, sql):\n  File "/usr/local/lib/python3.9/site-packages/litecli/packages/special/main.py", line 109, in execute\n    raise CommandNotFound\nlitecli.packages.special.main.CommandNotFound\n\nDuring handling of the above exception, another exception occurred:\n\nTraceback (most recent call last):\n  File "/usr/local/lib/python3.9/site-packages/litecli/main.py", line 441, in one_iteration\n    for title, cur, headers, status in res:\n  File "/usr/local/lib/python3.9/site-packages/litecli/sqlexecute.py", line 125, in run\n    cur.execute(sql)\nsqlite3.OperationalError: near "table": syntax error\n'
2020-12-10 13:37:04,104 (69844/MainThread) litecli.main ERROR - sql: 'select count(student_id) from ', error: OperationalError('incomplete input')
2020-12-10 13:37:04,105 (69844/MainThread) litecli.main ERROR - traceback: 'Traceback (most recent call last):\n  File "/usr/local/lib/python3.9/site-packages/litecli/sqlexecute.py", line 121, in run\n    for result in special.execute(cur, sql):\n  File "/usr/local/lib/python3.9/site-packages/litecli/packages/special/main.py", line 109, in execute\n    raise CommandNotFound\nlitecli.packages.special.main.CommandNotFound\n\nDuring handling of the above exception, another exception occurred:\n\nTraceback (most recent call last):\n  File "/usr/local/lib/python3.9/site-packages/litecli/main.py", line 441, in one_iteration\n    for title, cur, headers, status in res:\n  File "/usr/local/lib/python3.9/site-packages/litecli/sqlexecute.py", line 125, in run\n    cur.execute(sql)\nsqlite3.OperationalError: incomplete input\n'
2020-12-10 13:53:28,755 (69844/MainThread) litecli.main ERROR - sql: 'select grade ,avg(gpa),min(gpa),max(gpa),from student g', error: OperationalError('near "from": syntax error')
2020-12-10 13:53:28,756 (69844/MainThread) litecli.main ERROR - traceback: 'Traceback (most recent call last):\n  File "/usr/local/lib/python3.9/site-packages/litecli/sqlexecute.py", line 121, in run\n    for result in special.execute(cur, sql):\n  File "/usr/local/lib/python3.9/site-packages/litecli/packages/special/main.py", line 109, in execute\n    raise CommandNotFound\nlitecli.packages.special.main.CommandNotFound\n\nDuring handling of the above exception, another exception occurred:\n\nTraceback (most recent call last):\n  File "/usr/local/lib/python3.9/site-packages/litecli/main.py", line 441, in one_iteration\n    for title, cur, headers, status in res:\n  File "/usr/local/lib/python3.9/site-packages/litecli/sqlexecute.py", line 125, in run\n    cur.execute(sql)\nsqlite3.OperationalError: near "from": syntax error\n'
2020-12-10 13:54:14,388 (69844/MainThread) litecli.main ERROR - sql: 'select grade ,avg(gpa),min(gpa),max(gpa),from student group by grade;', error: OperationalError('near "from": syntax error')
2020-12-10 13:54:14,388 (69844/MainThread) litecli.main ERROR - traceback: 'Traceback (most recent call last):\n  File "/usr/local/lib/python3.9/site-packages/litecli/sqlexecute.py", line 121, in run\n    for result in special.execute(cur, sql):\n  File "/usr/local/lib/python3.9/site-packages/litecli/packages/special/main.py", line 109, in execute\n    raise CommandNotFound\nlitecli.packages.special.main.CommandNotFound\n\nDuring handling of the above exception, another exception occurred:\n\nTraceback (most recent call last):\n  File "/usr/local/lib/python3.9/site-packages/litecli/main.py", line 441, in one_iteration\n    for title, cur, headers, status in res:\n  File "/usr/local/lib/python3.9/site-packages/litecli/sqlexecute.py", line 125, in run\n    cur.execute(sql)\nsqlite3.OperationalError: near "from": syntax error\n'
2020-12-10 14:12:25,531 (69844/MainThread) litecli.main ERROR - sql: 'select * from student where gpa >=(select gpa from student where student_id = "J11014"', error: OperationalError('incomplete input')
2020-12-10 14:12:25,531 (69844/MainThread) litecli.main ERROR - traceback: 'Traceback (most recent call last):\n  File "/usr/local/lib/python3.9/site-packages/litecli/sqlexecute.py", line 121, in run\n    for result in special.execute(cur, sql):\n  File "/usr/local/lib/python3.9/site-packages/litecli/packages/special/main.py", line 109, in execute\n    raise CommandNotFound\nlitecli.packages.special.main.CommandNotFound\n\nDuring handling of the above exception, another exception occurred:\n\nTraceback (most recent call last):\n  File "/usr/local/lib/python3.9/site-packages/litecli/main.py", line 441, in one_iteration\n    for title, cur, headers, status in res:\n  File "/usr/local/lib/python3.9/site-packages/litecli/sqlexecute.py", line 125, in run\n    cur.execute(sql)\nsqlite3.OperationalError: incomplete input\n'
2020-12-10 14:25:09,676 (69844/MainThread) litecli.main ERROR - sql: 'select * from student where credit <=(select agv(credit) from student where grade=3) and grade=3', error: OperationalError('no such function: agv')
2020-12-10 14:25:09,676 (69844/MainThread) litecli.main ERROR - traceback: 'Traceback (most recent call last):\n  File "/usr/local/lib/python3.9/site-packages/litecli/sqlexecute.py", line 121, in run\n    for result in special.execute(cur, sql):\n  File "/usr/local/lib/python3.9/site-packages/litecli/packages/special/main.py", line 109, in execute\n    raise CommandNotFound\nlitecli.packages.special.main.CommandNotFound\n\nDuring handling of the above exception, another exception occurred:\n\nTraceback (most recent call last):\n  File "/usr/local/lib/python3.9/site-packages/litecli/main.py", line 441, in one_iteration\n    for title, cur, headers, status in res:\n  File "/usr/local/lib/python3.9/site-packages/litecli/sqlexecute.py", line 125, in run\n    cur.execute(sql)\nsqlite3.OperationalError: no such function: agv\n'
2020-12-17 10:51:48,541 (3541/MainThread) litecli.main ERROR - sql: 'ls', error: OperationalError('near "ls": syntax error')
2020-12-17 10:51:48,545 (3541/MainThread) litecli.main ERROR - traceback: 'Traceback (most recent call last):\n  File "/usr/local/lib/python3.9/site-packages/litecli/sqlexecute.py", line 121, in run\n    for result in special.execute(cur, sql):\n  File "/usr/local/lib/python3.9/site-packages/litecli/packages/special/main.py", line 109, in execute\n    raise CommandNotFound\nlitecli.packages.special.main.CommandNotFound\n\nDuring handling of the above exception, another exception occurred:\n\nTraceback (most recent call last):\n  File "/usr/local/lib/python3.9/site-packages/litecli/main.py", line 441, in one_iteration\n    for title, cur, headers, status in res:\n  File "/usr/local/lib/python3.9/site-packages/litecli/sqlexecute.py", line 125, in run\n    cur.execute(sql)\nsqlite3.OperationalError: near "ls": syntax error\n'
2020-12-17 13:18:25,965 (7527/MainThread) litecli.main ERROR - sql: '.heder on', error: OperationalError('near ".": syntax error')
2020-12-17 13:18:25,968 (7527/MainThread) litecli.main ERROR - traceback: 'Traceback (most recent call last):\n  File "/usr/local/lib/python3.9/site-packages/litecli/sqlexecute.py", line 121, in run\n    for result in special.execute(cur, sql):\n  File "/usr/local/lib/python3.9/site-packages/litecli/packages/special/main.py", line 109, in execute\n    raise CommandNotFound\nlitecli.packages.special.main.CommandNotFound\n\nDuring handling of the above exception, another exception occurred:\n\nTraceback (most recent call last):\n  File "/usr/local/lib/python3.9/site-packages/litecli/main.py", line 441, in one_iteration\n    for title, cur, headers, status in res:\n  File "/usr/local/lib/python3.9/site-packages/litecli/sqlexecute.py", line 125, in run\n    cur.execute(sql)\nsqlite3.OperationalError: near ".": syntax error\n'
2020-12-17 13:18:34,596 (7527/MainThread) litecli.main ERROR - sql: '.header on', error: OperationalError('near ".": syntax error')
2020-12-17 13:18:34,597 (7527/MainThread) litecli.main ERROR - traceback: 'Traceback (most recent call last):\n  File "/usr/local/lib/python3.9/site-packages/litecli/sqlexecute.py", line 121, in run\n    for result in special.execute(cur, sql):\n  File "/usr/local/lib/python3.9/site-packages/litecli/packages/special/main.py", line 109, in execute\n    raise CommandNotFound\nlitecli.packages.special.main.CommandNotFound\n\nDuring handling of the above exception, another exception occurred:\n\nTraceback (most recent call last):\n  File "/usr/local/lib/python3.9/site-packages/litecli/main.py", line 441, in one_iteration\n    for title, cur, headers, status in res:\n  File "/usr/local/lib/python3.9/site-packages/litecli/sqlexecute.py", line 125, in run\n    cur.execute(sql)\nsqlite3.OperationalError: near ".": syntax error\n'
2020-12-17 13:18:39,838 (7527/MainThread) litecli.main ERROR - sql: 'header on', error: OperationalError('near "header": syntax error')
2020-12-17 13:18:39,839 (7527/MainThread) litecli.main ERROR - traceback: 'Traceback (most recent call last):\n  File "/usr/local/lib/python3.9/site-packages/litecli/sqlexecute.py", line 121, in run\n    for result in special.execute(cur, sql):\n  File "/usr/local/lib/python3.9/site-packages/litecli/packages/special/main.py", line 109, in execute\n    raise CommandNotFound\nlitecli.packages.special.main.CommandNotFound\n\nDuring handling of the above exception, another exception occurred:\n\nTraceback (most recent call last):\n  File "/usr/local/lib/python3.9/site-packages/litecli/main.py", line 441, in one_iteration\n    for title, cur, headers, status in res:\n  File "/usr/local/lib/python3.9/site-packages/litecli/sqlexecute.py", line 125, in run\n    cur.execute(sql)\nsqlite3.OperationalError: near "header": syntax error\n'
2020-12-17 13:18:55,264 (7527/MainThread) litecli.main ERROR - sql: '.header on', error: OperationalError('near ".": syntax error')
2020-12-17 13:18:55,265 (7527/MainThread) litecli.main ERROR - traceback: 'Traceback (most recent call last):\n  File "/usr/local/lib/python3.9/site-packages/litecli/sqlexecute.py", line 121, in run\n    for result in special.execute(cur, sql):\n  File "/usr/local/lib/python3.9/site-packages/litecli/packages/special/main.py", line 109, in execute\n    raise CommandNotFound\nlitecli.packages.special.main.CommandNotFound\n\nDuring handling of the above exception, another exception occurred:\n\nTraceback (most recent call last):\n  File "/usr/local/lib/python3.9/site-packages/litecli/main.py", line 441, in one_iteration\n    for title, cur, headers, status in res:\n  File "/usr/local/lib/python3.9/site-packages/litecli/sqlexecute.py", line 125, in run\n    cur.execute(sql)\nsqlite3.OperationalError: near ".": syntax error\n'
2020-12-17 13:34:00,452 (7527/MainThread) litecli.main ERROR - sql: 'database', error: OperationalError('near "database": syntax error')
2020-12-17 13:34:00,454 (7527/MainThread) litecli.main ERROR - traceback: 'Traceback (most recent call last):\n  File "/usr/local/lib/python3.9/site-packages/litecli/sqlexecute.py", line 121, in run\n    for result in special.execute(cur, sql):\n  File "/usr/local/lib/python3.9/site-packages/litecli/packages/special/main.py", line 109, in execute\n    raise CommandNotFound\nlitecli.packages.special.main.CommandNotFound\n\nDuring handling of the above exception, another exception occurred:\n\nTraceback (most recent call last):\n  File "/usr/local/lib/python3.9/site-packages/litecli/main.py", line 441, in one_iteration\n    for title, cur, headers, status in res:\n  File "/usr/local/lib/python3.9/site-packages/litecli/sqlexecute.py", line 125, in run\n    cur.execute(sql)\nsqlite3.OperationalError: near "database": syntax error\n'
2020-12-17 13:44:00,165 (7527/MainThread) litecli.main ERROR - sql: '.separator', error: OperationalError('near ".": syntax error')
2020-12-17 13:44:00,166 (7527/MainThread) litecli.main ERROR - traceback: 'Traceback (most recent call last):\n  File "/usr/local/lib/python3.9/site-packages/litecli/sqlexecute.py", line 121, in run\n    for result in special.execute(cur, sql):\n  File "/usr/local/lib/python3.9/site-packages/litecli/packages/special/main.py", line 109, in execute\n    raise CommandNotFound\nlitecli.packages.special.main.CommandNotFound\n\nDuring handling of the above exception, another exception occurred:\n\nTraceback (most recent call last):\n  File "/usr/local/lib/python3.9/site-packages/litecli/main.py", line 441, in one_iteration\n    for title, cur, headers, status in res:\n  File "/usr/local/lib/python3.9/site-packages/litecli/sqlexecute.py", line 125, in run\n    cur.execute(sql)\nsqlite3.OperationalError: near ".": syntax error\n'
2020-12-17 13:44:09,661 (7527/MainThread) litecli.main ERROR - sql: 'separator', error: OperationalError('near "separator": syntax error')
2020-12-17 13:44:09,662 (7527/MainThread) litecli.main ERROR - traceback: 'Traceback (most recent call last):\n  File "/usr/local/lib/python3.9/site-packages/litecli/sqlexecute.py", line 121, in run\n    for result in special.execute(cur, sql):\n  File "/usr/local/lib/python3.9/site-packages/litecli/packages/special/main.py", line 109, in execute\n    raise CommandNotFound\nlitecli.packages.special.main.CommandNotFound\n\nDuring handling of the above exception, another exception occurred:\n\nTraceback (most recent call last):\n  File "/usr/local/lib/python3.9/site-packages/litecli/main.py", line 441, in one_iteration\n    for title, cur, headers, status in res:\n  File "/usr/local/lib/python3.9/site-packages/litecli/sqlexecute.py", line 125, in run\n    cur.execute(sql)\nsqlite3.OperationalError: near "separator": syntax error\n'
2020-12-17 13:44:17,944 (7527/MainThread) litecli.main ERROR - sql: 'separator', error: OperationalError('near "separator": syntax error')
2020-12-17 13:44:17,945 (7527/MainThread) litecli.main ERROR - traceback: 'Traceback (most recent call last):\n  File "/usr/local/lib/python3.9/site-packages/litecli/sqlexecute.py", line 121, in run\n    for result in special.execute(cur, sql):\n  File "/usr/local/lib/python3.9/site-packages/litecli/packages/special/main.py", line 109, in execute\n    raise CommandNotFound\nlitecli.packages.special.main.CommandNotFound\n\nDuring handling of the above exception, another exception occurred:\n\nTraceback (most recent call last):\n  File "/usr/local/lib/python3.9/site-packages/litecli/main.py", line 441, in one_iteration\n    for title, cur, headers, status in res:\n  File "/usr/local/lib/python3.9/site-packages/litecli/sqlexecute.py", line 125, in run\n    cur.execute(sql)\nsqlite3.OperationalError: near "separator": syntax error\n'
2020-12-17 13:44:40,599 (7527/MainThread) litecli.main ERROR - sql: '.separator ,', error: OperationalError('near ".": syntax error')
2020-12-17 13:44:40,600 (7527/MainThread) litecli.main ERROR - traceback: 'Traceback (most recent call last):\n  File "/usr/local/lib/python3.9/site-packages/litecli/sqlexecute.py", line 121, in run\n    for result in special.execute(cur, sql):\n  File "/usr/local/lib/python3.9/site-packages/litecli/packages/special/main.py", line 109, in execute\n    raise CommandNotFound\nlitecli.packages.special.main.CommandNotFound\n\nDuring handling of the above exception, another exception occurred:\n\nTraceback (most recent call last):\n  File "/usr/local/lib/python3.9/site-packages/litecli/main.py", line 441, in one_iteration\n    for title, cur, headers, status in res:\n  File "/usr/local/lib/python3.9/site-packages/litecli/sqlexecute.py", line 125, in run\n    cur.execute(sql)\nsqlite3.OperationalError: near ".": syntax error\n'
2020-12-17 13:44:47,652 (7527/MainThread) litecli.main ERROR - sql: 'separator ,', error: OperationalError('near "separator": syntax error')
2020-12-17 13:44:47,652 (7527/MainThread) litecli.main ERROR - traceback: 'Traceback (most recent call last):\n  File "/usr/local/lib/python3.9/site-packages/litecli/sqlexecute.py", line 121, in run\n    for result in special.execute(cur, sql):\n  File "/usr/local/lib/python3.9/site-packages/litecli/packages/special/main.py", line 109, in execute\n    raise CommandNotFound\nlitecli.packages.special.main.CommandNotFound\n\nDuring handling of the above exception, another exception occurred:\n\nTraceback (most recent call last):\n  File "/usr/local/lib/python3.9/site-packages/litecli/main.py", line 441, in one_iteration\n    for title, cur, headers, status in res:\n  File "/usr/local/lib/python3.9/site-packages/litecli/sqlexecute.py", line 125, in run\n    cur.execute(sql)\nsqlite3.OperationalError: near "separator": syntax error\n'
2020-12-17 13:50:03,050 (7527/MainThread) litecli.main ERROR - sql: 'create table subject (subject_code INTEGER PRIMARY KEY,', error: OperationalError('incomplete input')
2020-12-17 13:50:03,050 (7527/MainThread) litecli.main ERROR - traceback: 'Traceback (most recent call last):\n  File "/usr/local/lib/python3.9/site-packages/litecli/sqlexecute.py", line 121, in run\n    for result in special.execute(cur, sql):\n  File "/usr/local/lib/python3.9/site-packages/litecli/packages/special/main.py", line 109, in execute\n    raise CommandNotFound\nlitecli.packages.special.main.CommandNotFound\n\nDuring handling of the above exception, another exception occurred:\n\nTraceback (most recent call last):\n  File "/usr/local/lib/python3.9/site-packages/litecli/main.py", line 441, in one_iteration\n    for title, cur, headers, status in res:\n  File "/usr/local/lib/python3.9/site-packages/litecli/sqlexecute.py", line 125, in run\n    cur.execute(sql)\nsqlite3.OperationalError: incomplete input\n'
2020-12-17 13:53:07,332 (7527/MainThread) litecli.main ERROR - sql: '.import  subject_data.csv  subject', error: IntegrityError('datatype mismatch')
2020-12-17 13:53:07,334 (7527/MainThread) litecli.main ERROR - traceback: 'Traceback (most recent call last):\n  File "/usr/local/lib/python3.9/site-packages/litecli/main.py", line 441, in one_iteration\n    for title, cur, headers, status in res:\n  File "/usr/local/lib/python3.9/site-packages/litecli/sqlexecute.py", line 121, in run\n    for result in special.execute(cur, sql):\n  File "/usr/local/lib/python3.9/site-packages/litecli/packages/special/main.py", line 121, in execute\n    return special_cmd.handler(cur=cur, arg=arg, verbose=verbose)\n  File "/usr/local/lib/python3.9/site-packages/litecli/packages/special/dbcommands.py", line 266, in import_file\n    cur.execute(insert_tmpl, row)\nsqlite3.IntegrityError: datatype mismatch\n'
2020-12-17 13:56:49,558 (7527/MainThread) litecli.main ERROR - sql: '.tables\\', error: OperationalError('near ".": syntax error')
2020-12-17 13:56:49,559 (7527/MainThread) litecli.main ERROR - traceback: 'Traceback (most recent call last):\n  File "/usr/local/lib/python3.9/site-packages/litecli/sqlexecute.py", line 121, in run\n    for result in special.execute(cur, sql):\n  File "/usr/local/lib/python3.9/site-packages/litecli/packages/special/main.py", line 109, in execute\n    raise CommandNotFound\nlitecli.packages.special.main.CommandNotFound\n\nDuring handling of the above exception, another exception occurred:\n\nTraceback (most recent call last):\n  File "/usr/local/lib/python3.9/site-packages/litecli/main.py", line 441, in one_iteration\n    for title, cur, headers, status in res:\n  File "/usr/local/lib/python3.9/site-packages/litecli/sqlexecute.py", line 125, in run\n    cur.execute(sql)\nsqlite3.OperationalError: near ".": syntax error\n'
2020-12-17 13:57:33,715 (7527/MainThread) litecli.main ERROR - sql: '.import  subject_data.csv  subject', error: OperationalError('cannot start a transaction within a transaction')
2020-12-17 13:57:33,716 (7527/MainThread) litecli.main ERROR - traceback: 'Traceback (most recent call last):\n  File "/usr/local/lib/python3.9/site-packages/litecli/main.py", line 441, in one_iteration\n    for title, cur, headers, status in res:\n  File "/usr/local/lib/python3.9/site-packages/litecli/sqlexecute.py", line 121, in run\n    for result in special.execute(cur, sql):\n  File "/usr/local/lib/python3.9/site-packages/litecli/packages/special/main.py", line 121, in execute\n    return special_cmd.handler(cur=cur, arg=arg, verbose=verbose)\n  File "/usr/local/lib/python3.9/site-packages/litecli/packages/special/dbcommands.py", line 255, in import_file\n    cur.execute("BEGIN")\nsqlite3.OperationalError: cannot start a transaction within a transaction\n'
2020-12-17 14:01:32,770 (7527/MainThread) litecli.main ERROR - sql: '.import subject_data.csv subject', error: OperationalError('cannot start a transaction within a transaction')
2020-12-17 14:01:32,771 (7527/MainThread) litecli.main ERROR - traceback: 'Traceback (most recent call last):\n  File "/usr/local/lib/python3.9/site-packages/litecli/main.py", line 441, in one_iteration\n    for title, cur, headers, status in res:\n  File "/usr/local/lib/python3.9/site-packages/litecli/sqlexecute.py", line 121, in run\n    for result in special.execute(cur, sql):\n  File "/usr/local/lib/python3.9/site-packages/litecli/packages/special/main.py", line 121, in execute\n    return special_cmd.handler(cur=cur, arg=arg, verbose=verbose)\n  File "/usr/local/lib/python3.9/site-packages/litecli/packages/special/dbcommands.py", line 255, in import_file\n    cur.execute("BEGIN")\nsqlite3.OperationalError: cannot start a transaction within a transaction\n'
2020-12-17 14:02:46,693 (7527/MainThread) litecli.main ERROR - sql: '.separator ,', error: OperationalError('near ".": syntax error')
2020-12-17 14:02:46,693 (7527/MainThread) litecli.main ERROR - traceback: 'Traceback (most recent call last):\n  File "/usr/local/lib/python3.9/site-packages/litecli/sqlexecute.py", line 121, in run\n    for result in special.execute(cur, sql):\n  File "/usr/local/lib/python3.9/site-packages/litecli/packages/special/main.py", line 109, in execute\n    raise CommandNotFound\nlitecli.packages.special.main.CommandNotFound\n\nDuring handling of the above exception, another exception occurred:\n\nTraceback (most recent call last):\n  File "/usr/local/lib/python3.9/site-packages/litecli/main.py", line 441, in one_iteration\n    for title, cur, headers, status in res:\n  File "/usr/local/lib/python3.9/site-packages/litecli/sqlexecute.py", line 125, in run\n    cur.execute(sql)\nsqlite3.OperationalError: near ".": syntax error\n'
2020-12-17 14:02:57,335 (7527/MainThread) litecli.main ERROR - sql: 'separator ,', error: OperationalError('near "separator": syntax error')
2020-12-17 14:02:57,336 (7527/MainThread) litecli.main ERROR - traceback: 'Traceback (most recent call last):\n  File "/usr/local/lib/python3.9/site-packages/litecli/sqlexecute.py", line 121, in run\n    for result in special.execute(cur, sql):\n  File "/usr/local/lib/python3.9/site-packages/litecli/packages/special/main.py", line 109, in execute\n    raise CommandNotFound\nlitecli.packages.special.main.CommandNotFound\n\nDuring handling of the above exception, another exception occurred:\n\nTraceback (most recent call last):\n  File "/usr/local/lib/python3.9/site-packages/litecli/main.py", line 441, in one_iteration\n    for title, cur, headers, status in res:\n  File "/usr/local/lib/python3.9/site-packages/litecli/sqlexecute.py", line 125, in run\n    cur.execute(sql)\nsqlite3.OperationalError: near "separator": syntax error\n'
2020-12-17 14:04:04,860 (7527/MainThread) litecli.main ERROR - sql: '.import subject_data.csv subject', error: OperationalError('cannot start a transaction within a transaction')
2020-12-17 14:04:04,860 (7527/MainThread) litecli.main ERROR - traceback: 'Traceback (most recent call last):\n  File "/usr/local/lib/python3.9/site-packages/litecli/main.py", line 441, in one_iteration\n    for title, cur, headers, status in res:\n  File "/usr/local/lib/python3.9/site-packages/litecli/sqlexecute.py", line 121, in run\n    for result in special.execute(cur, sql):\n  File "/usr/local/lib/python3.9/site-packages/litecli/packages/special/main.py", line 121, in execute\n    return special_cmd.handler(cur=cur, arg=arg, verbose=verbose)\n  File "/usr/local/lib/python3.9/site-packages/litecli/packages/special/dbcommands.py", line 255, in import_file\n    cur.execute("BEGIN")\nsqlite3.OperationalError: cannot start a transaction within a transaction\n'
2020-12-17 14:14:17,999 (8611/MainThread) litecli.main ERROR - sql: '.import subject_data.csv subject', error: IntegrityError('datatype mismatch')
2020-12-17 14:14:18,005 (8611/MainThread) litecli.main ERROR - traceback: 'Traceback (most recent call last):\n  File "/usr/local/lib/python3.9/site-packages/litecli/main.py", line 441, in one_iteration\n    for title, cur, headers, status in res:\n  File "/usr/local/lib/python3.9/site-packages/litecli/sqlexecute.py", line 121, in run\n    for result in special.execute(cur, sql):\n  File "/usr/local/lib/python3.9/site-packages/litecli/packages/special/main.py", line 121, in execute\n    return special_cmd.handler(cur=cur, arg=arg, verbose=verbose)\n  File "/usr/local/lib/python3.9/site-packages/litecli/packages/special/dbcommands.py", line 266, in import_file\n    cur.execute(insert_tmpl, row)\nsqlite3.IntegrityError: datatype mismatch\n'
2020-12-17 14:21:22,404 (8611/MainThread) litecli.main ERROR - sql: '.import subject_data.csv subject', error: OperationalError('cannot start a transaction within a transaction')
2020-12-17 14:21:22,404 (8611/MainThread) litecli.main ERROR - traceback: 'Traceback (most recent call last):\n  File "/usr/local/lib/python3.9/site-packages/litecli/main.py", line 441, in one_iteration\n    for title, cur, headers, status in res:\n  File "/usr/local/lib/python3.9/site-packages/litecli/sqlexecute.py", line 121, in run\n    for result in special.execute(cur, sql):\n  File "/usr/local/lib/python3.9/site-packages/litecli/packages/special/main.py", line 121, in execute\n    return special_cmd.handler(cur=cur, arg=arg, verbose=verbose)\n  File "/usr/local/lib/python3.9/site-packages/litecli/packages/special/dbcommands.py", line 255, in import_file\n    cur.execute("BEGIN")\nsqlite3.OperationalError: cannot start a transaction within a transaction\n'
2020-12-17 14:39:00,122 (8933/MainThread) litecli.main ERROR - sql: 'ls', error: OperationalError('near "ls": syntax error')
2020-12-17 14:39:00,128 (8933/MainThread) litecli.main ERROR - traceback: 'Traceback (most recent call last):\n  File "/usr/local/lib/python3.9/site-packages/litecli/sqlexecute.py", line 121, in run\n    for result in special.execute(cur, sql):\n  File "/usr/local/lib/python3.9/site-packages/litecli/packages/special/main.py", line 109, in execute\n    raise CommandNotFound\nlitecli.packages.special.main.CommandNotFound\n\nDuring handling of the above exception, another exception occurred:\n\nTraceback (most recent call last):\n  File "/usr/local/lib/python3.9/site-packages/litecli/main.py", line 441, in one_iteration\n    for title, cur, headers, status in res:\n  File "/usr/local/lib/python3.9/site-packages/litecli/sqlexecute.py", line 125, in run\n    cur.execute(sql)\nsqlite3.OperationalError: near "ls": syntax error\n'
2020-12-17 14:40:35,157 (8933/MainThread) litecli.main ERROR - sql: '.import subject_data.csv subject', error: IntegrityError('datatype mismatch')
2020-12-17 14:40:35,158 (8933/MainThread) litecli.main ERROR - traceback: 'Traceback (most recent call last):\n  File "/usr/local/lib/python3.9/site-packages/litecli/main.py", line 441, in one_iteration\n    for title, cur, headers, status in res:\n  File "/usr/local/lib/python3.9/site-packages/litecli/sqlexecute.py", line 121, in run\n    for result in special.execute(cur, sql):\n  File "/usr/local/lib/python3.9/site-packages/litecli/packages/special/main.py", line 121, in execute\n    return special_cmd.handler(cur=cur, arg=arg, verbose=verbose)\n  File "/usr/local/lib/python3.9/site-packages/litecli/packages/special/dbcommands.py", line 266, in import_file\n    cur.execute(insert_tmpl, row)\nsqlite3.IntegrityError: datatype mismatch\n'
2020-12-17 14:42:46,086 (8933/MainThread) litecli.main ERROR - sql: '.import subject_data.csv subject', error: OperationalError('cannot start a transaction within a transaction')
2020-12-17 14:42:46,086 (8933/MainThread) litecli.main ERROR - traceback: 'Traceback (most recent call last):\n  File "/usr/local/lib/python3.9/site-packages/litecli/main.py", line 441, in one_iteration\n    for title, cur, headers, status in res:\n  File "/usr/local/lib/python3.9/site-packages/litecli/sqlexecute.py", line 121, in run\n    for result in special.execute(cur, sql):\n  File "/usr/local/lib/python3.9/site-packages/litecli/packages/special/main.py", line 121, in execute\n    return special_cmd.handler(cur=cur, arg=arg, verbose=verbose)\n  File "/usr/local/lib/python3.9/site-packages/litecli/packages/special/dbcommands.py", line 255, in import_file\n    cur.execute("BEGIN")\nsqlite3.OperationalError: cannot start a transaction within a transaction\n'
2020-12-17 14:45:34,175 (9228/MainThread) litecli.main ERROR - sql: '.separator ,', error: OperationalError('near ".": syntax error')
2020-12-17 14:45:34,177 (9228/MainThread) litecli.main ERROR - traceback: 'Traceback (most recent call last):\n  File "/usr/local/lib/python3.9/site-packages/litecli/sqlexecute.py", line 121, in run\n    for result in special.execute(cur, sql):\n  File "/usr/local/lib/python3.9/site-packages/litecli/packages/special/main.py", line 109, in execute\n    raise CommandNotFound\nlitecli.packages.special.main.CommandNotFound\n\nDuring handling of the above exception, another exception occurred:\n\nTraceback (most recent call last):\n  File "/usr/local/lib/python3.9/site-packages/litecli/main.py", line 441, in one_iteration\n    for title, cur, headers, status in res:\n  File "/usr/local/lib/python3.9/site-packages/litecli/sqlexecute.py", line 125, in run\n    cur.execute(sql)\nsqlite3.OperationalError: near ".": syntax error\n'
2020-12-17 14:45:59,782 (9228/MainThread) litecli.main ERROR - sql: '.import subject_data.csv subject', error: IntegrityError('datatype mismatch')
2020-12-17 14:45:59,782 (9228/MainThread) litecli.main ERROR - traceback: 'Traceback (most recent call last):\n  File "/usr/local/lib/python3.9/site-packages/litecli/main.py", line 441, in one_iteration\n    for title, cur, headers, status in res:\n  File "/usr/local/lib/python3.9/site-packages/litecli/sqlexecute.py", line 121, in run\n    for result in special.execute(cur, sql):\n  File "/usr/local/lib/python3.9/site-packages/litecli/packages/special/main.py", line 121, in execute\n    return special_cmd.handler(cur=cur, arg=arg, verbose=verbose)\n  File "/usr/local/lib/python3.9/site-packages/litecli/packages/special/dbcommands.py", line 266, in import_file\n    cur.execute(insert_tmpl, row)\nsqlite3.IntegrityError: datatype mismatch\n'
2020-12-17 14:46:24,198 (9228/MainThread) litecli.main ERROR - sql: '.import subject_data.csv subject', error: OperationalError('cannot start a transaction within a transaction')
2020-12-17 14:46:24,199 (9228/MainThread) litecli.main ERROR - traceback: 'Traceback (most recent call last):\n  File "/usr/local/lib/python3.9/site-packages/litecli/main.py", line 441, in one_iteration\n    for title, cur, headers, status in res:\n  File "/usr/local/lib/python3.9/site-packages/litecli/sqlexecute.py", line 121, in run\n    for result in special.execute(cur, sql):\n  File "/usr/local/lib/python3.9/site-packages/litecli/packages/special/main.py", line 121, in execute\n    return special_cmd.handler(cur=cur, arg=arg, verbose=verbose)\n  File "/usr/local/lib/python3.9/site-packages/litecli/packages/special/dbcommands.py", line 255, in import_file\n    cur.execute("BEGIN")\nsqlite3.OperationalError: cannot start a transaction within a transaction\n'
2020-12-17 14:51:45,822 (9358/MainThread) litecli.main ERROR - sql: 'exit.', error: OperationalError('near "exit": syntax error')
2020-12-17 14:51:45,824 (9358/MainThread) litecli.main ERROR - traceback: 'Traceback (most recent call last):\n  File "/usr/local/lib/python3.9/site-packages/litecli/sqlexecute.py", line 121, in run\n    for result in special.execute(cur, sql):\n  File "/usr/local/lib/python3.9/site-packages/litecli/packages/special/main.py", line 109, in execute\n    raise CommandNotFound\nlitecli.packages.special.main.CommandNotFound\n\nDuring handling of the above exception, another exception occurred:\n\nTraceback (most recent call last):\n  File "/usr/local/lib/python3.9/site-packages/litecli/main.py", line 441, in one_iteration\n    for title, cur, headers, status in res:\n  File "/usr/local/lib/python3.9/site-packages/litecli/sqlexecute.py", line 125, in run\n    cur.execute(sql)\nsqlite3.OperationalError: near "exit": syntax error\n'
2020-12-17 15:05:57,702 (9956/MainThread) litecli.main ERROR - sql: 'ls', error: OperationalError('near "ls": syntax error')
2020-12-17 15:05:57,703 (9956/MainThread) litecli.main ERROR - traceback: 'Traceback (most recent call last):\n  File "/usr/local/lib/python3.9/site-packages/litecli/sqlexecute.py", line 121, in run\n    for result in special.execute(cur, sql):\n  File "/usr/local/lib/python3.9/site-packages/litecli/packages/special/main.py", line 109, in execute\n    raise CommandNotFound\nlitecli.packages.special.main.CommandNotFound\n\nDuring handling of the above exception, another exception occurred:\n\nTraceback (most recent call last):\n  File "/usr/local/lib/python3.9/site-packages/litecli/main.py", line 441, in one_iteration\n    for title, cur, headers, status in res:\n  File "/usr/local/lib/python3.9/site-packages/litecli/sqlexecute.py", line 125, in run\n    cur.execute(sql)\nsqlite3.OperationalError: near "ls": syntax error\n'
2020-12-17 15:06:48,154 (10023/MainThread) litecli.main ERROR - sql: '.separator  ,\n', error: OperationalError('near ".": syntax error')
2020-12-17 15:06:48,155 (10023/MainThread) litecli.main ERROR - traceback: 'Traceback (most recent call last):\n  File "/usr/local/lib/python3.9/site-packages/litecli/sqlexecute.py", line 121, in run\n    for result in special.execute(cur, sql):\n  File "/usr/local/lib/python3.9/site-packages/litecli/packages/special/main.py", line 109, in execute\n    raise CommandNotFound\nlitecli.packages.special.main.CommandNotFound\n\nDuring handling of the above exception, another exception occurred:\n\nTraceback (most recent call last):\n  File "/usr/local/lib/python3.9/site-packages/litecli/main.py", line 441, in one_iteration\n    for title, cur, headers, status in res:\n  File "/usr/local/lib/python3.9/site-packages/litecli/sqlexecute.py", line 125, in run\n    cur.execute(sql)\nsqlite3.OperationalError: near ".": syntax error\n'
2020-12-17 15:07:06,548 (10023/MainThread) litecli.main ERROR - sql: '.import subject_data.csv subject', error: IntegrityError('datatype mismatch')
2020-12-17 15:07:06,549 (10023/MainThread) litecli.main ERROR - traceback: 'Traceback (most recent call last):\n  File "/usr/local/lib/python3.9/site-packages/litecli/main.py", line 441, in one_iteration\n    for title, cur, headers, status in res:\n  File "/usr/local/lib/python3.9/site-packages/litecli/sqlexecute.py", line 121, in run\n    for result in special.execute(cur, sql):\n  File "/usr/local/lib/python3.9/site-packages/litecli/packages/special/main.py", line 121, in execute\n    return special_cmd.handler(cur=cur, arg=arg, verbose=verbose)\n  File "/usr/local/lib/python3.9/site-packages/litecli/packages/special/dbcommands.py", line 266, in import_file\n    cur.execute(insert_tmpl, row)\nsqlite3.IntegrityError: datatype mismatch\n'
2020-12-17 15:07:09,685 (10023/MainThread) litecli.main ERROR - sql: '.import subject_data.csv subject', error: OperationalError('cannot start a transaction within a transaction')
2020-12-17 15:07:09,685 (10023/MainThread) litecli.main ERROR - traceback: 'Traceback (most recent call last):\n  File "/usr/local/lib/python3.9/site-packages/litecli/main.py", line 441, in one_iteration\n    for title, cur, headers, status in res:\n  File "/usr/local/lib/python3.9/site-packages/litecli/sqlexecute.py", line 121, in run\n    for result in special.execute(cur, sql):\n  File "/usr/local/lib/python3.9/site-packages/litecli/packages/special/main.py", line 121, in execute\n    return special_cmd.handler(cur=cur, arg=arg, verbose=verbose)\n  File "/usr/local/lib/python3.9/site-packages/litecli/packages/special/dbcommands.py", line 255, in import_file\n    cur.execute("BEGIN")\nsqlite3.OperationalError: cannot start a transaction within a transaction\n'
2020-12-17 15:07:11,259 (10023/MainThread) litecli.main ERROR - sql: '.import subject_data.csv subject', error: OperationalError('cannot start a transaction within a transaction')
2020-12-17 15:07:11,259 (10023/MainThread) litecli.main ERROR - traceback: 'Traceback (most recent call last):\n  File "/usr/local/lib/python3.9/site-packages/litecli/main.py", line 441, in one_iteration\n    for title, cur, headers, status in res:\n  File "/usr/local/lib/python3.9/site-packages/litecli/sqlexecute.py", line 121, in run\n    for result in special.execute(cur, sql):\n  File "/usr/local/lib/python3.9/site-packages/litecli/packages/special/main.py", line 121, in execute\n    return special_cmd.handler(cur=cur, arg=arg, verbose=verbose)\n  File "/usr/local/lib/python3.9/site-packages/litecli/packages/special/dbcommands.py", line 255, in import_file\n    cur.execute("BEGIN")\nsqlite3.OperationalError: cannot start a transaction within a transaction\n'
2020-12-17 15:07:12,587 (10023/MainThread) litecli.main ERROR - sql: '.import subject_data.csv subject', error: OperationalError('cannot start a transaction within a transaction')
2020-12-17 15:07:12,587 (10023/MainThread) litecli.main ERROR - traceback: 'Traceback (most recent call last):\n  File "/usr/local/lib/python3.9/site-packages/litecli/main.py", line 441, in one_iteration\n    for title, cur, headers, status in res:\n  File "/usr/local/lib/python3.9/site-packages/litecli/sqlexecute.py", line 121, in run\n    for result in special.execute(cur, sql):\n  File "/usr/local/lib/python3.9/site-packages/litecli/packages/special/main.py", line 121, in execute\n    return special_cmd.handler(cur=cur, arg=arg, verbose=verbose)\n  File "/usr/local/lib/python3.9/site-packages/litecli/packages/special/dbcommands.py", line 255, in import_file\n    cur.execute("BEGIN")\nsqlite3.OperationalError: cannot start a transaction within a transaction\n'
2020-12-17 15:07:13,525 (10023/MainThread) litecli.main ERROR - sql: '.import subject_data.csv subject', error: OperationalError('cannot start a transaction within a transaction')
2020-12-17 15:07:13,526 (10023/MainThread) litecli.main ERROR - traceback: 'Traceback (most recent call last):\n  File "/usr/local/lib/python3.9/site-packages/litecli/main.py", line 441, in one_iteration\n    for title, cur, headers, status in res:\n  File "/usr/local/lib/python3.9/site-packages/litecli/sqlexecute.py", line 121, in run\n    for result in special.execute(cur, sql):\n  File "/usr/local/lib/python3.9/site-packages/litecli/packages/special/main.py", line 121, in execute\n    return special_cmd.handler(cur=cur, arg=arg, verbose=verbose)\n  File "/usr/local/lib/python3.9/site-packages/litecli/packages/special/dbcommands.py", line 255, in import_file\n    cur.execute("BEGIN")\nsqlite3.OperationalError: cannot start a transaction within a transaction\n'
2020-12-17 15:07:14,277 (10023/MainThread) litecli.main ERROR - sql: '.import subject_data.csv subject', error: OperationalError('cannot start a transaction within a transaction')
2020-12-17 15:07:14,277 (10023/MainThread) litecli.main ERROR - traceback: 'Traceback (most recent call last):\n  File "/usr/local/lib/python3.9/site-packages/litecli/main.py", line 441, in one_iteration\n    for title, cur, headers, status in res:\n  File "/usr/local/lib/python3.9/site-packages/litecli/sqlexecute.py", line 121, in run\n    for result in special.execute(cur, sql):\n  File "/usr/local/lib/python3.9/site-packages/litecli/packages/special/main.py", line 121, in execute\n    return special_cmd.handler(cur=cur, arg=arg, verbose=verbose)\n  File "/usr/local/lib/python3.9/site-packages/litecli/packages/special/dbcommands.py", line 255, in import_file\n    cur.execute("BEGIN")\nsqlite3.OperationalError: cannot start a transaction within a transaction\n'
2020-12-17 15:07:14,949 (10023/MainThread) litecli.main ERROR - sql: '.import subject_data.csv subject', error: OperationalError('cannot start a transaction within a transaction')
2020-12-17 15:07:14,949 (10023/MainThread) litecli.main ERROR - traceback: 'Traceback (most recent call last):\n  File "/usr/local/lib/python3.9/site-packages/litecli/main.py", line 441, in one_iteration\n    for title, cur, headers, status in res:\n  File "/usr/local/lib/python3.9/site-packages/litecli/sqlexecute.py", line 121, in run\n    for result in special.execute(cur, sql):\n  File "/usr/local/lib/python3.9/site-packages/litecli/packages/special/main.py", line 121, in execute\n    return special_cmd.handler(cur=cur, arg=arg, verbose=verbose)\n  File "/usr/local/lib/python3.9/site-packages/litecli/packages/special/dbcommands.py", line 255, in import_file\n    cur.execute("BEGIN")\nsqlite3.OperationalError: cannot start a transaction within a transaction\n'
2020-12-17 15:07:15,602 (10023/MainThread) litecli.main ERROR - sql: '.import subject_data.csv subject', error: OperationalError('cannot start a transaction within a transaction')
2020-12-17 15:07:15,602 (10023/MainThread) litecli.main ERROR - traceback: 'Traceback (most recent call last):\n  File "/usr/local/lib/python3.9/site-packages/litecli/main.py", line 441, in one_iteration\n    for title, cur, headers, status in res:\n  File "/usr/local/lib/python3.9/site-packages/litecli/sqlexecute.py", line 121, in run\n    for result in special.execute(cur, sql):\n  File "/usr/local/lib/python3.9/site-packages/litecli/packages/special/main.py", line 121, in execute\n    return special_cmd.handler(cur=cur, arg=arg, verbose=verbose)\n  File "/usr/local/lib/python3.9/site-packages/litecli/packages/special/dbcommands.py", line 255, in import_file\n    cur.execute("BEGIN")\nsqlite3.OperationalError: cannot start a transaction within a transaction\n'
2020-12-17 15:07:16,219 (10023/MainThread) litecli.main ERROR - sql: '.import subject_data.csv subject', error: OperationalError('cannot start a transaction within a transaction')
2020-12-17 15:07:16,219 (10023/MainThread) litecli.main ERROR - traceback: 'Traceback (most recent call last):\n  File "/usr/local/lib/python3.9/site-packages/litecli/main.py", line 441, in one_iteration\n    for title, cur, headers, status in res:\n  File "/usr/local/lib/python3.9/site-packages/litecli/sqlexecute.py", line 121, in run\n    for result in special.execute(cur, sql):\n  File "/usr/local/lib/python3.9/site-packages/litecli/packages/special/main.py", line 121, in execute\n    return special_cmd.handler(cur=cur, arg=arg, verbose=verbose)\n  File "/usr/local/lib/python3.9/site-packages/litecli/packages/special/dbcommands.py", line 255, in import_file\n    cur.execute("BEGIN")\nsqlite3.OperationalError: cannot start a transaction within a transaction\n'
2020-12-17 15:12:18,128 (10252/MainThread) litecli.main ERROR - sql: 'ls', error: OperationalError('near "ls": syntax error')
2020-12-17 15:12:18,129 (10252/MainThread) litecli.main ERROR - traceback: 'Traceback (most recent call last):\n  File "/usr/local/lib/python3.9/site-packages/litecli/sqlexecute.py", line 121, in run\n    for result in special.execute(cur, sql):\n  File "/usr/local/lib/python3.9/site-packages/litecli/packages/special/main.py", line 109, in execute\n    raise CommandNotFound\nlitecli.packages.special.main.CommandNotFound\n\nDuring handling of the above exception, another exception occurred:\n\nTraceback (most recent call last):\n  File "/usr/local/lib/python3.9/site-packages/litecli/main.py", line 441, in one_iteration\n    for title, cur, headers, status in res:\n  File "/usr/local/lib/python3.9/site-packages/litecli/sqlexecute.py", line 125, in run\n    cur.execute(sql)\nsqlite3.OperationalError: near "ls": syntax error\n'
2020-12-17 15:17:46,921 (10252/MainThread) litecli.main ERROR - sql: 'select * subject.subject_code, subject.subject_name , teacher.name from subject inner join teacher on subject.teacher_id = teacher.teacher_id:', error: OperationalError('near "subject": syntax error')
2020-12-17 15:17:46,923 (10252/MainThread) litecli.main ERROR - traceback: 'Traceback (most recent call last):\n  File "/usr/local/lib/python3.9/site-packages/litecli/sqlexecute.py", line 121, in run\n    for result in special.execute(cur, sql):\n  File "/usr/local/lib/python3.9/site-packages/litecli/packages/special/main.py", line 109, in execute\n    raise CommandNotFound\nlitecli.packages.special.main.CommandNotFound\n\nDuring handling of the above exception, another exception occurred:\n\nTraceback (most recent call last):\n  File "/usr/local/lib/python3.9/site-packages/litecli/main.py", line 441, in one_iteration\n    for title, cur, headers, status in res:\n  File "/usr/local/lib/python3.9/site-packages/litecli/sqlexecute.py", line 125, in run\n    cur.execute(sql)\nsqlite3.OperationalError: near "subject": syntax error\n'
2020-12-17 15:17:50,878 (10252/MainThread) litecli.main ERROR - sql: 'select * subject.subject_code, subject.subject_name , teacher.name from subject inner join teacher on subject.teacher_id = teacher.teacher_id;', error: OperationalError('near "subject": syntax error')
2020-12-17 15:17:50,879 (10252/MainThread) litecli.main ERROR - traceback: 'Traceback (most recent call last):\n  File "/usr/local/lib/python3.9/site-packages/litecli/sqlexecute.py", line 121, in run\n    for result in special.execute(cur, sql):\n  File "/usr/local/lib/python3.9/site-packages/litecli/packages/special/main.py", line 109, in execute\n    raise CommandNotFound\nlitecli.packages.special.main.CommandNotFound\n\nDuring handling of the above exception, another exception occurred:\n\nTraceback (most recent call last):\n  File "/usr/local/lib/python3.9/site-packages/litecli/main.py", line 441, in one_iteration\n    for title, cur, headers, status in res:\n  File "/usr/local/lib/python3.9/site-packages/litecli/sqlexecute.py", line 125, in run\n    cur.execute(sql)\nsqlite3.OperationalError: near "subject": syntax error\n'
2021-01-07 13:19:01,529 (96133/MainThread) litecli.main ERROR - sql: '.explain', error: OperationalError('near ".": syntax error')
2021-01-07 13:19:01,533 (96133/MainThread) litecli.main ERROR - traceback: 'Traceback (most recent call last):\n  File "/usr/local/lib/python3.9/site-packages/litecli/sqlexecute.py", line 121, in run\n    for result in special.execute(cur, sql):\n  File "/usr/local/lib/python3.9/site-packages/litecli/packages/special/main.py", line 109, in execute\n    raise CommandNotFound\nlitecli.packages.special.main.CommandNotFound\n\nDuring handling of the above exception, another exception occurred:\n\nTraceback (most recent call last):\n  File "/usr/local/lib/python3.9/site-packages/litecli/main.py", line 441, in one_iteration\n    for title, cur, headers, status in res:\n  File "/usr/local/lib/python3.9/site-packages/litecli/sqlexecute.py", line 125, in run\n    cur.execute(sql)\nsqlite3.OperationalError: near ".": syntax error\n'
2021-01-07 13:19:06,913 (96133/MainThread) litecli.main ERROR - sql: 'explain', error: OperationalError('incomplete input')
2021-01-07 13:19:06,913 (96133/MainThread) litecli.main ERROR - traceback: 'Traceback (most recent call last):\n  File "/usr/local/lib/python3.9/site-packages/litecli/sqlexecute.py", line 121, in run\n    for result in special.execute(cur, sql):\n  File "/usr/local/lib/python3.9/site-packages/litecli/packages/special/main.py", line 109, in execute\n    raise CommandNotFound\nlitecli.packages.special.main.CommandNotFound\n\nDuring handling of the above exception, another exception occurred:\n\nTraceback (most recent call last):\n  File "/usr/local/lib/python3.9/site-packages/litecli/main.py", line 441, in one_iteration\n    for title, cur, headers, status in res:\n  File "/usr/local/lib/python3.9/site-packages/litecli/sqlexecute.py", line 125, in run\n    cur.execute(sql)\nsqlite3.OperationalError: incomplete input\n'
2021-01-07 13:31:31,083 (96133/MainThread) litecli.main ERROR - sql: '.separator  ,', error: OperationalError('near ".": syntax error')
2021-01-07 13:31:31,083 (96133/MainThread) litecli.main ERROR - traceback: 'Traceback (most recent call last):\n  File "/usr/local/lib/python3.9/site-packages/litecli/sqlexecute.py", line 121, in run\n    for result in special.execute(cur, sql):\n  File "/usr/local/lib/python3.9/site-packages/litecli/packages/special/main.py", line 109, in execute\n    raise CommandNotFound\nlitecli.packages.special.main.CommandNotFound\n\nDuring handling of the above exception, another exception occurred:\n\nTraceback (most recent call last):\n  File "/usr/local/lib/python3.9/site-packages/litecli/main.py", line 441, in one_iteration\n    for title, cur, headers, status in res:\n  File "/usr/local/lib/python3.9/site-packages/litecli/sqlexecute.py", line 125, in run\n    cur.execute(sql)\nsqlite3.OperationalError: near ".": syntax error\n'
2021-01-07 13:31:42,255 (96133/MainThread) litecli.main ERROR - sql: 'separator ,', error: OperationalError('near "separator": syntax error')
2021-01-07 13:31:42,256 (96133/MainThread) litecli.main ERROR - traceback: 'Traceback (most recent call last):\n  File "/usr/local/lib/python3.9/site-packages/litecli/sqlexecute.py", line 121, in run\n    for result in special.execute(cur, sql):\n  File "/usr/local/lib/python3.9/site-packages/litecli/packages/special/main.py", line 109, in execute\n    raise CommandNotFound\nlitecli.packages.special.main.CommandNotFound\n\nDuring handling of the above exception, another exception occurred:\n\nTraceback (most recent call last):\n  File "/usr/local/lib/python3.9/site-packages/litecli/main.py", line 441, in one_iteration\n    for title, cur, headers, status in res:\n  File "/usr/local/lib/python3.9/site-packages/litecli/sqlexecute.py", line 125, in run\n    cur.execute(sql)\nsqlite3.OperationalError: near "separator": syntax error\n'
2021-01-07 13:36:53,765 (96133/MainThread) litecli.main ERROR - sql: 'ls', error: OperationalError('near "ls": syntax error')
2021-01-07 13:36:53,767 (96133/MainThread) litecli.main ERROR - traceback: 'Traceback (most recent call last):\n  File "/usr/local/lib/python3.9/site-packages/litecli/sqlexecute.py", line 121, in run\n    for result in special.execute(cur, sql):\n  File "/usr/local/lib/python3.9/site-packages/litecli/packages/special/main.py", line 109, in execute\n    raise CommandNotFound\nlitecli.packages.special.main.CommandNotFound\n\nDuring handling of the above exception, another exception occurred:\n\nTraceback (most recent call last):\n  File "/usr/local/lib/python3.9/site-packages/litecli/main.py", line 441, in one_iteration\n    for title, cur, headers, status in res:\n  File "/usr/local/lib/python3.9/site-packages/litecli/sqlexecute.py", line 125, in run\n    cur.execute(sql)\nsqlite3.OperationalError: near "ls": syntax error\n'
2021-01-07 14:24:44,662 (96133/MainThread) litecli.main ERROR - sql: 'select title,name ,price from book inner join publisher on book,publisher_id=publisher.publisher_id', error: OperationalError('near "=": syntax error')
2021-01-07 14:24:44,664 (96133/MainThread) litecli.main ERROR - traceback: 'Traceback (most recent call last):\n  File "/usr/local/lib/python3.9/site-packages/litecli/sqlexecute.py", line 121, in run\n    for result in special.execute(cur, sql):\n  File "/usr/local/lib/python3.9/site-packages/litecli/packages/special/main.py", line 109, in execute\n    raise CommandNotFound\nlitecli.packages.special.main.CommandNotFound\n\nDuring handling of the above exception, another exception occurred:\n\nTraceback (most recent call last):\n  File "/usr/local/lib/python3.9/site-packages/litecli/main.py", line 441, in one_iteration\n    for title, cur, headers, status in res:\n  File "/usr/local/lib/python3.9/site-packages/litecli/sqlexecute.py", line 125, in run\n    cur.execute(sql)\nsqlite3.OperationalError: near "=": syntax error\n'
2021-01-07 14:24:59,169 (96133/MainThread) litecli.main ERROR - sql: 'select title,name ,price from book inner join publisher on book,publisher_id = publisher.publisher_id', error: OperationalError('near "=": syntax error')
2021-01-07 14:24:59,169 (96133/MainThread) litecli.main ERROR - traceback: 'Traceback (most recent call last):\n  File "/usr/local/lib/python3.9/site-packages/litecli/sqlexecute.py", line 121, in run\n    for result in special.execute(cur, sql):\n  File "/usr/local/lib/python3.9/site-packages/litecli/packages/special/main.py", line 109, in execute\n    raise CommandNotFound\nlitecli.packages.special.main.CommandNotFound\n\nDuring handling of the above exception, another exception occurred:\n\nTraceback (most recent call last):\n  File "/usr/local/lib/python3.9/site-packages/litecli/main.py", line 441, in one_iteration\n    for title, cur, headers, status in res:\n  File "/usr/local/lib/python3.9/site-packages/litecli/sqlexecute.py", line 125, in run\n    cur.execute(sql)\nsqlite3.OperationalError: near "=": syntax error\n'
2021-01-13 16:45:26,363 (48799/MainThread) litecli.main ERROR - sql: 'select book.title, publisher.name, book.price from book inner join publisher on book.publisher_id=publisher.publisher_id', error: OperationalError('no such column: book.publisher_id')
2021-01-13 16:45:26,369 (48799/MainThread) litecli.main ERROR - traceback: 'Traceback (most recent call last):\n  File "/usr/local/lib/python3.9/site-packages/litecli/sqlexecute.py", line 121, in run\n    for result in special.execute(cur, sql):\n  File "/usr/local/lib/python3.9/site-packages/litecli/packages/special/main.py", line 109, in execute\n    raise CommandNotFound\nlitecli.packages.special.main.CommandNotFound\n\nDuring handling of the above exception, another exception occurred:\n\nTraceback (most recent call last):\n  File "/usr/local/lib/python3.9/site-packages/litecli/main.py", line 441, in one_iteration\n    for title, cur, headers, status in res:\n  File "/usr/local/lib/python3.9/site-packages/litecli/sqlexecute.py", line 125, in run\n    cur.execute(sql)\nsqlite3.OperationalError: no such column: book.publisher_id\n'
2021-01-13 16:48:07,645 (48799/MainThread) litecli.main ERROR - sql: 'select title, name, price from book inner join publisher on book.publisher_id=publisher.publisher_id;', error: OperationalError('no such column: book.publisher_id')
2021-01-13 16:48:07,645 (48799/MainThread) litecli.main ERROR - traceback: 'Traceback (most recent call last):\n  File "/usr/local/lib/python3.9/site-packages/litecli/sqlexecute.py", line 121, in run\n    for result in special.execute(cur, sql):\n  File "/usr/local/lib/python3.9/site-packages/litecli/packages/special/main.py", line 109, in execute\n    raise CommandNotFound\nlitecli.packages.special.main.CommandNotFound\n\nDuring handling of the above exception, another exception occurred:\n\nTraceback (most recent call last):\n  File "/usr/local/lib/python3.9/site-packages/litecli/main.py", line 441, in one_iteration\n    for title, cur, headers, status in res:\n  File "/usr/local/lib/python3.9/site-packages/litecli/sqlexecute.py", line 125, in run\n    cur.execute(sql)\nsqlite3.OperationalError: no such column: book.publisher_id\n'
2021-01-13 16:59:57,669 (49178/MainThread) litecli.main ERROR - sql: 'delete from book where publisher_id = P0001;', error: OperationalError('no such column: P0001')
2021-01-13 16:59:57,670 (49178/MainThread) litecli.main ERROR - traceback: 'Traceback (most recent call last):\n  File "/usr/local/lib/python3.9/site-packages/litecli/sqlexecute.py", line 121, in run\n    for result in special.execute(cur, sql):\n  File "/usr/local/lib/python3.9/site-packages/litecli/packages/special/main.py", line 109, in execute\n    raise CommandNotFound\nlitecli.packages.special.main.CommandNotFound\n\nDuring handling of the above exception, another exception occurred:\n\nTraceback (most recent call last):\n  File "/usr/local/lib/python3.9/site-packages/litecli/main.py", line 441, in one_iteration\n    for title, cur, headers, status in res:\n  File "/usr/local/lib/python3.9/site-packages/litecli/sqlexecute.py", line 125, in run\n    cur.execute(sql)\nsqlite3.OperationalError: no such column: P0001\n'
2021-01-13 17:04:30,162 (49178/MainThread) litecli.main ERROR - sql: 'insert into book values(4526052914,ＲＦＩＤハンドブック[第２版],クラウス・フィンケンツェラ－\u3000ソフト工学研究所,P0074,2004-05-01,3600)', error: OperationalError('near "[第２版]": syntax error')
2021-01-13 17:04:30,163 (49178/MainThread) litecli.main ERROR - traceback: 'Traceback (most recent call last):\n  File "/usr/local/lib/python3.9/site-packages/litecli/sqlexecute.py", line 121, in run\n    for result in special.execute(cur, sql):\n  File "/usr/local/lib/python3.9/site-packages/litecli/packages/special/main.py", line 109, in execute\n    raise CommandNotFound\nlitecli.packages.special.main.CommandNotFound\n\nDuring handling of the above exception, another exception occurred:\n\nTraceback (most recent call last):\n  File "/usr/local/lib/python3.9/site-packages/litecli/main.py", line 441, in one_iteration\n    for title, cur, headers, status in res:\n  File "/usr/local/lib/python3.9/site-packages/litecli/sqlexecute.py", line 125, in run\n    cur.execute(sql)\nsqlite3.OperationalError: near "[第２版]": syntax error\n'
2021-01-13 17:04:59,658 (49178/MainThread) litecli.main ERROR - sql: 'insert into book values(4526052914,"ＲＦＩＤハンドブック[第２版]","クラウス・フィンケンツェラ－\u3000ソフト工学研究所","P0074","2004-05-01,3600")', error: OperationalError('table book has 6 columns but 5 values were supplied')
2021-01-13 17:04:59,658 (49178/MainThread) litecli.main ERROR - traceback: 'Traceback (most recent call last):\n  File "/usr/local/lib/python3.9/site-packages/litecli/sqlexecute.py", line 121, in run\n    for result in special.execute(cur, sql):\n  File "/usr/local/lib/python3.9/site-packages/litecli/packages/special/main.py", line 109, in execute\n    raise CommandNotFound\nlitecli.packages.special.main.CommandNotFound\n\nDuring handling of the above exception, another exception occurred:\n\nTraceback (most recent call last):\n  File "/usr/local/lib/python3.9/site-packages/litecli/main.py", line 441, in one_iteration\n    for title, cur, headers, status in res:\n  File "/usr/local/lib/python3.9/site-packages/litecli/sqlexecute.py", line 125, in run\n    cur.execute(sql)\nsqlite3.OperationalError: table book has 6 columns but 5 values were supplied\n'
2021-01-13 17:06:26,746 (49178/MainThread) litecli.main ERROR - sql: 'insert into book values("4526052914","ＲＦＩＤハンドブック[第２版]","クラウス・フィンケンツェラ－\u3000ソフト工学研究所","P0074","2004-05-01",3600)', error: IntegrityError('UNIQUE constraint failed: book.isbn')
2021-01-13 17:06:26,746 (49178/MainThread) litecli.main ERROR - traceback: 'Traceback (most recent call last):\n  File "/usr/local/lib/python3.9/site-packages/litecli/sqlexecute.py", line 121, in run\n    for result in special.execute(cur, sql):\n  File "/usr/local/lib/python3.9/site-packages/litecli/packages/special/main.py", line 109, in execute\n    raise CommandNotFound\nlitecli.packages.special.main.CommandNotFound\n\nDuring handling of the above exception, another exception occurred:\n\nTraceback (most recent call last):\n  File "/usr/local/lib/python3.9/site-packages/litecli/main.py", line 441, in one_iteration\n    for title, cur, headers, status in res:\n  File "/usr/local/lib/python3.9/site-packages/litecli/sqlexecute.py", line 125, in run\n    cur.execute(sql)\nsqlite3.IntegrityError: UNIQUE constraint failed: book.isbn\n'
2021-01-13 17:06:49,284 (49178/MainThread) litecli.main ERROR - sql: 'insert into book values(4526052914,"ＲＦＩＤハンドブック[第２版]","クラウス・フィンケンツェラ－\u3000ソフト工学研究所","P0074","2004-05-01",3600)', error: IntegrityError('UNIQUE constraint failed: book.isbn')
2021-01-13 17:06:49,284 (49178/MainThread) litecli.main ERROR - traceback: 'Traceback (most recent call last):\n  File "/usr/local/lib/python3.9/site-packages/litecli/sqlexecute.py", line 121, in run\n    for result in special.execute(cur, sql):\n  File "/usr/local/lib/python3.9/site-packages/litecli/packages/special/main.py", line 109, in execute\n    raise CommandNotFound\nlitecli.packages.special.main.CommandNotFound\n\nDuring handling of the above exception, another exception occurred:\n\nTraceback (most recent call last):\n  File "/usr/local/lib/python3.9/site-packages/litecli/main.py", line 441, in one_iteration\n    for title, cur, headers, status in res:\n  File "/usr/local/lib/python3.9/site-packages/litecli/sqlexecute.py", line 125, in run\n    cur.execute(sql)\nsqlite3.IntegrityError: UNIQUE constraint failed: book.isbn\n'
2021-01-13 17:09:53,688 (49178/MainThread) litecli.main ERROR - sql: 'ls', error: OperationalError('near "ls": syntax error')
2021-01-13 17:09:53,689 (49178/MainThread) litecli.main ERROR - traceback: 'Traceback (most recent call last):\n  File "/usr/local/lib/python3.9/site-packages/litecli/sqlexecute.py", line 121, in run\n    for result in special.execute(cur, sql):\n  File "/usr/local/lib/python3.9/site-packages/litecli/packages/special/main.py", line 109, in execute\n    raise CommandNotFound\nlitecli.packages.special.main.CommandNotFound\n\nDuring handling of the above exception, another exception occurred:\n\nTraceback (most recent call last):\n  File "/usr/local/lib/python3.9/site-packages/litecli/main.py", line 441, in one_iteration\n    for title, cur, headers, status in res:\n  File "/usr/local/lib/python3.9/site-packages/litecli/sqlexecute.py", line 125, in run\n    cur.execute(sql)\nsqlite3.OperationalError: near "ls": syntax error\n'
2021-01-13 17:11:20,024 (49178/MainThread) litecli.main ERROR - sql: 'delete from publisher where publisher_id = P0001;', error: OperationalError('no such column: P0001')
2021-01-13 17:11:20,025 (49178/MainThread) litecli.main ERROR - traceback: 'Traceback (most recent call last):\n  File "/usr/local/lib/python3.9/site-packages/litecli/sqlexecute.py", line 121, in run\n    for result in special.execute(cur, sql):\n  File "/usr/local/lib/python3.9/site-packages/litecli/packages/special/main.py", line 109, in execute\n    raise CommandNotFound\nlitecli.packages.special.main.CommandNotFound\n\nDuring handling of the above exception, another exception occurred:\n\nTraceback (most recent call last):\n  File "/usr/local/lib/python3.9/site-packages/litecli/main.py", line 441, in one_iteration\n    for title, cur, headers, status in res:\n  File "/usr/local/lib/python3.9/site-packages/litecli/sqlexecute.py", line 125, in run\n    cur.execute(sql)\nsqlite3.OperationalError: no such column: P0001\n'
2021-01-13 17:13:58,774 (49178/MainThread) litecli.main ERROR - sql: 'ls', error: OperationalError('near "ls": syntax error')
2021-01-13 17:13:58,774 (49178/MainThread) litecli.main ERROR - traceback: 'Traceback (most recent call last):\n  File "/usr/local/lib/python3.9/site-packages/litecli/sqlexecute.py", line 121, in run\n    for result in special.execute(cur, sql):\n  File "/usr/local/lib/python3.9/site-packages/litecli/packages/special/main.py", line 109, in execute\n    raise CommandNotFound\nlitecli.packages.special.main.CommandNotFound\n\nDuring handling of the above exception, another exception occurred:\n\nTraceback (most recent call last):\n  File "/usr/local/lib/python3.9/site-packages/litecli/main.py", line 441, in one_iteration\n    for title, cur, headers, status in res:\n  File "/usr/local/lib/python3.9/site-packages/litecli/sqlexecute.py", line 125, in run\n    cur.execute(sql)\nsqlite3.OperationalError: near "ls": syntax error\n'
2021-01-14 02:06:39,252 (54003/MainThread) litecli.main ERROR - sql: 'ls', error: OperationalError('near "ls": syntax error')
2021-01-14 02:06:39,258 (54003/MainThread) litecli.main ERROR - traceback: 'Traceback (most recent call last):\n  File "/usr/local/lib/python3.9/site-packages/litecli/sqlexecute.py", line 121, in run\n    for result in special.execute(cur, sql):\n  File "/usr/local/lib/python3.9/site-packages/litecli/packages/special/main.py", line 109, in execute\n    raise CommandNotFound\nlitecli.packages.special.main.CommandNotFound\n\nDuring handling of the above exception, another exception occurred:\n\nTraceback (most recent call last):\n  File "/usr/local/lib/python3.9/site-packages/litecli/main.py", line 441, in one_iteration\n    for title, cur, headers, status in res:\n  File "/usr/local/lib/python3.9/site-packages/litecli/sqlexecute.py", line 125, in run\n    cur.execute(sql)\nsqlite3.OperationalError: near "ls": syntax error\n'
2021-01-21 00:07:14,999 (97700/MainThread) litecli.main ERROR - sql: '.ex', error: OperationalError('Not connected to database.')
2021-01-21 00:07:15,003 (97700/MainThread) litecli.main ERROR - traceback: 'Traceback (most recent call last):\n  File "/usr/local/lib/python3.9/site-packages/litecli/main.py", line 441, in one_iteration\n    for title, cur, headers, status in res:\n  File "/usr/local/lib/python3.9/site-packages/litecli/sqlexecute.py", line 114, in run\n    raise OperationalError("Not connected to database.")\nsqlite3.OperationalError: Not connected to database.\n'
2021-01-21 00:07:19,037 (97700/MainThread) litecli.main ERROR - sql: '.exit', error: OperationalError('Not connected to database.')
2021-01-21 00:07:19,037 (97700/MainThread) litecli.main ERROR - traceback: 'Traceback (most recent call last):\n  File "/usr/local/lib/python3.9/site-packages/litecli/main.py", line 441, in one_iteration\n    for title, cur, headers, status in res:\n  File "/usr/local/lib/python3.9/site-packages/litecli/sqlexecute.py", line 114, in run\n    raise OperationalError("Not connected to database.")\nsqlite3.OperationalError: Not connected to database.\n'
2021-01-21 00:07:22,490 (97700/MainThread) litecli.main ERROR - sql: '.exit', error: OperationalError('Not connected to database.')
2021-01-21 00:07:22,491 (97700/MainThread) litecli.main ERROR - traceback: 'Traceback (most recent call last):\n  File "/usr/local/lib/python3.9/site-packages/litecli/main.py", line 441, in one_iteration\n    for title, cur, headers, status in res:\n  File "/usr/local/lib/python3.9/site-packages/litecli/sqlexecute.py", line 114, in run\n    raise OperationalError("Not connected to database.")\nsqlite3.OperationalError: Not connected to database.\n'
2021-01-21 00:07:32,822 (97700/MainThread) litecli.main ERROR - sql: '.exit', error: OperationalError('Not connected to database.')
2021-01-21 00:07:32,822 (97700/MainThread) litecli.main ERROR - traceback: 'Traceback (most recent call last):\n  File "/usr/local/lib/python3.9/site-packages/litecli/main.py", line 441, in one_iteration\n    for title, cur, headers, status in res:\n  File "/usr/local/lib/python3.9/site-packages/litecli/sqlexecute.py", line 114, in run\n    raise OperationalError("Not connected to database.")\nsqlite3.OperationalError: Not connected to database.\n'
